Workbook

Sheet Hypothèses
A1: Modèle financier — {{NOM_BOUTIQUE}} · boutique Pokémon JCC FR, ventes Suisse
A2: Source : business plan du 4 octobre 2026 (BP). Toutes les valeurs sont des hypothèses de gestion, pas des devis. Montants en CHF.
A3: Légende : cellules jaunes à texte bleu = entrées à modifier ; texte noir = formules (ne pas écraser) ; texte vert = lien vers une autre feuille ; gris italique = valeur publiée dans le BP (référence de contrôle).
A5: Paramètres généraux
A6: Paramètre | B6: Valeur | C6: Unité | D6: Source / statut | E6: Nom défini
A7: TVA sur ventes (taux normal) | B7: 0.081 | C7: % | D7: BP §4 [S6] — statut TVA à confirmer avec la fiduciaire | E7: TVA
A8: Seuil d'assujettissement TVA | B8: 100000 | C8: CHF/an | D8: BP §4 [S6] — CA déterminant de toute l'entité | E8: Seuil_TVA
A9: Panier produits moyen TTC | B9: 95 | C9: CHF | D9: BP §10 — hypothèse | E9: Panier_TTC
A10: Panier produits moyen HT | B10: =Panier_TTC/(1+TVA) -> 87.881591 | C10: CHF | D10: Calcul | E10: Panier_HT
A11: Contribution produit avant acquisition | B11: 0.22 | C11: % CA HT | D11: BP §10 — après achat, paiement, emballage, provision SAV | E11: Taux_contribution
A12: Charges fixes mensuelles | B12: ='Charges mensuelles'!B7 -> 400 | C12: CHF/mois | D12: Lien feuille Charges mensuelles (BP §3) | E12: Charges_fixes
A13: Rémunération budgétée | B13: 2000 | C13: CHF/mois | D13: BP §10 — hors cotisations sociales | E13: Remuneration
A14: Coût produit en % du CA net | B14: 0.7 | C14: % | D14: BP §10 — « par hypothèse » | E14: Cout_produit_pct
A15: Stock initial acheté rendu Suisse | B15: ='Budget initial'!B5 -> 3000 | C15: CHF | D15: Lien feuille Budget initial (BP §3) | E15: Stock_initial
A16: Jours par mois (convention) | B16: 30 | C16: jours | D16: Convention de calcul | E16: Jours_mois
A17: Semaines par mois | B17: =52/12 -> 4.3333333 | C17: sem. | D17: Convention 52/12 | E17: Semaines_mois
A18: Plancher dur : contribution par commande | B18: 8 | C18: CHF | D18: BP §5 | E18: Plancher_CHF
A19: Plancher dur : contribution en % du CA net | B19: 0.12 | C19: % | D19: BP §5 | E19: Plancher_pct
A20: Supervision au lancement — minimum | B20: 6 | C20: h/semaine | D20: BP §3 | E20: Heures_min
A21: Supervision au lancement — maximum | B21: 10 | C21: h/semaine | D21: BP §3 | E21: Heures_max
A22: Préparation d'une commande (colis) | B22: 15 | C22: minutes | D22: HYPOTHÈSE FICTIVE — à mesurer lors des commandes tests | E22: Minutes_prep
A25: Scénarios mensuels (BP §10)
A26: Paramètre | B26: Prudent | C26: Central | D26: Développement | E26: Source
A27: Commandes payées par mois | B27: 40 | C27: 100 | D27: 200 | E27: BP §10 — simulations, pas une prévision de demande
A28: CAC moyen mélangé (CHF/commande) | B28: 8 | C28: 6 | D28: 5 | E28: BP §10 — CAC sur commandes payées après annulations
A30: Sensibilité (BP §10)
A31: Paramètre | B31: Valeur | C31: Unité | D31: Source | E31: Nom défini
A32: Contribution dégradée | B32: 0.15 | C32: % CA HT | D32: BP §10 | E32: Taux_sensibilite
A33: CAC élevé | B33: 15 | C33: CHF | D33: BP §10 | E33: CAC_eleve
A35: Délais du cycle cash — HYPOTHÈSES FICTIVES à remplacer (devis fournisseur, contrat PSP)
A36: Paramètre | B36: Valeur | C36: Unité | D36: Source / statut | E36: Nom défini
A37: Paiement fournisseur → réception (prépaiement) | B37: 14 | C37: jours | D37: FICTIF — BP §4 : ne pas supposer de facture HT/à terme avant confirmation | E37: Delai_prepaiement
A38: Jours de ventes détenus en stock | B38: 30 | C38: jours | D38: FICTIF — politique de stock à décider | E38: Jours_stock
A39: Crédit fournisseur après réception | B39: 0 | C39: jours | D39: FICTIF — 0 = prépaiement (prudent) | E39: Credit_fournisseur
A40: Délai de versement PSP | B40: 7 | C40: jours | D40: FICTIF — BP §7 : tester les délais de versement | E40: Delai_PSP
A42: Étoile polaire et stop-loss du mandat — décisions de la propriétaire
A43: Paramètre | B43: Valeur | C43: Unité | D43: Source / statut | E43: Nom défini
A44: Capital engagé de référence | B44: ='Budget initial'!B12 -> 8000 | C44: CHF | D44: Lien Budget initial (BP §3) — HYPOTHÈSE : remplacer par le capital réellement engagé | E44: Capital_engage
A45: Stop-loss global : perte cumulée maximale | B45: 0.2 | C45: % capital | D45: Mandat propriétaire — gel total, réarmement par la propriétaire uniquement | E45: StopLoss_global_pct
A46: Perte cumulée déclenchant le gel global | B46: =Capital_engage*StopLoss_global_pct -> 1600 | C46: CHF | D46: Calcul — comparée à la contribution nette cumulée | E46: Perte_max
...

Sheet Étoile polaire
A1: Étoile polaire — contribution nette cumulée (métrique unique de pilotage)
A2: Contribution nette = ventes nettes HT − coût historique − paiement − logistique − SAV − acquisition − charges fixes. Ni chiffre d'affaires ni followers.
A3: Légende : cellules jaunes à texte bleu = entrées à modifier ; texte noir = formules (ne pas écraser) ; texte vert = lien vers une autre feuille ; gris italique = valeur publiée dans le BP (référence de contrôle). Colonnes M à T : saisir le réel chaque lundi (montants HT, CHF).
A5: Paramètres (à modifier dans la feuille Hypothèses, lignes 44 à 54)
A6: Scénario projeté | E6: =CHOOSE(Scenario_choisi,"Prudent","Central","Développement") -> Central | F6: Choix en Hypothèses!B49 (1, 2 ou 3)
A7: Commandes par mois du scénario | E7: =INDEX(Hypothèses!$B$27:$D$27,Scenario_choisi) -> 100 | F7: BP §10 — simulation, pas une prévision de demande
A8: CAC moyen du scénario (CHF/commande) | E8: =INDEX(Hypothèses!$B$28:$D$28,Scenario_choisi) -> 6 | F8: BP §10
A9: Commandes par semaine (× 12/52) | E9: =E7*12/52 -> 23.076923 | F9: Volumes mensuels ramenés à la semaine
A10: Semaine d'ouverture des ventes | E10: =Semaine_ouverture -> 5 | F10: BP §9 — charges fixes dues dès la semaine 1
A11: Charges fixes par semaine (× 12/52) | E11: =Charges_fixes*12/52 -> 92.307692 | F11: BP §3 : 400 CHF/mois
A12: Logistique nette implicite par commande (emballage) | E12: =Panier_HT*(1-Taux_contribution-Cout_produit_pct)-(Frais_paiement_pct*Panier_TTC+Frais_paiement_fixe)-Provision_SAV -> 3.3555273 | F12: Solde des 8 % de CA HT restant après coût produit 70 % et contribution 22 % (BP §10), moins paiement et SAV | R12: =IF(E12<0,"INCOHÉRENT : hypothèses incompatibles","OK — cohérent") -> OK — cohérent
A13: Seuil du stop-loss global (contribution nette cumulée) | E13: =-Perte_max -> -1600 | F13: 20 % du capital engagé ⇒ tout gelé, retour au niveau d'autonomie 1
A14: Réserve de trésorerie = seuil du stop-loss cash | E14: =Reserve_cash -> 1600 | F14: Suivi dans tresorerie_13_semaines.xlsx (lignes 50-51)
A16: Synthèse
A17: Indicateur | E17: Projection | F17: Réel | G17: Commentaire / contrôle
A18: Contribution nette cumulée (fin de période / à date) | E18: =L92 -> 9969.9139 | F18: =IF(COUNT($V$41:$V$92)=0,"pas de saisie",SUM($V$41:$V$92)) -> pas de saisie | G18: La métrique étoile polaire : elle doit croître semaine après semaine
A19: Semaines couvertes | E19: =COUNT($K$41:$K$92) -> 52 | F19: =COUNT($V$41:$V$92) -> 0
A20: Cumul le plus bas | E20: =MIN($L$41:$L$92) -> -369.23077 | F20: =IF(COUNT($V$41:$V$92)=0,"",MIN($W$41:$W$92)) | G20: Creux de trésorerie d'exploitation à financer
A21: Semaine du cumul le plus bas | E21: =INDEX($A$41:$A$92,MATCH(E20,$L$41:$L$92,0)) -> 4 | F21: =IF(COUNT($V$41:$V$92)=0,"",INDEX($A$41:$A$92,MATCH(F20,$W$41:$W$92,0)))
A22: Retour à un cumul positif (semaine) | E22: =IF(MIN($Z$41:$Z$92)=0,"au-delà de 52 sem.",MIN($Z$41:$Z$92)) -> 6 | F22: =IF(COUNT($V$41:$V$92)=0,"",IF(MIN($AB$41:$AB$92)=0,"pas encore",MIN($AB$41:$AB$92))) | G22: Première semaine après le creux où le cumul redevient > 0
A23: Stop-loss global déclenché ? | E23: =IF(MIN($AA$41:$AA$92)=0,"non","OUI — semaine "&MIN($AA$41:$AA$92)) -> non | F23: =IF(COUNT($V$41:$V$92)=0,"",IF(MIN($AC$41:$AC$92)=0,"non","OUI — semaine "&MIN($AC$41:$AC$92)&" : TOUT GELER")) | G23: Perte cumulée ≥ seuil (ligne 13). Réarmement : propriétaire uniquement
A24: Équivalent mensuel en régime (dernière semaine × 52/12) | E24: =K92*52/12 -> 933.395 | F24: ="" | G24: =IF(ROUND(E24-INDEX(Scénarios!$B$15:$D$15,Scenario_choisi),6)=0,"OK — égal au résultat avant rémunération du scénario (feuille Scénarios)","ÉCART") -> OK — égal au résultat avant rémunération du scénario (feuille Scénarios)
A25: Jalon BP §1 : commandes payées sur la fenêtre de validation | E25: =SUMIFS($B$41:$B$92,$A$41:$A$92,">="&Semaine_ouverture,$A$41:$A$92,"<="&Semaine_ouverture+INT(Jours_validation/7)-1) -> 184.61538 | F25: =IF(COUNT($V$41:$V$92)=0,"",SUMIFS($M$41:$M$92,$A$41:$A$92,">="&Semaine_ouverture,$A$41:$A$92,"<="&Semaine_ouverture+INT(Jours_validation/7)-1)) | G25: ="Semaines "&Semaine_ouverture&" à "&(Semaine_ouverture+INT(Jours_validation/7)-1)&" ("&INT(Jours_validation/7)*7&" jours pleins ≈ 60 j du BP) ; cible : "&Commandes_validation&" commandes" -> Semaines 5 à 12 (56 jours pleins ≈ 60 j du BP) ; cible : 30 commandes
A26: Jalon commandes atteint ? | E26: =IF(E25>=Commandes_validation,"oui","NON") -> oui | F26: =IF(F25="","",IF(F25>=Commandes_validation,"oui","NON"))
A27: Jalon BP §1 : contribution après publicité sur la fenêtre | E27: =SUMIFS($I$41:$I$92,$A$41:$A$92,">="&Semaine_ouverture,$A$41:$A$92,"<="&Semaine_ouverture+INT(Jours_validation/7)-1) -> 2461.6523 | F27: =IF(COUNT($V$41:$V$92)=0,"",SUMIFS($U$41:$U$92,$A$41:$A$92,">="&Semaine_ouverture,$A$41:$A$92,"<="&Semaine_ouverture+INT(Jours_validation/7)-1)) | G27: Avant charges fixes
A28: Jalon contribution positive ? | E28: =IF(E27>0,"oui","NON") -> oui | F28: =IF(F27="","",IF(F27>0,"oui","NON")) | G28: Survente et écoulement de 50 % du stock pilote : suivis hors de ce classeur
A30: Stop-loss du mandat — rappel (pokeshop.stoploss, agent gouvernance, fait foi)
A31: Niveau | C31: Déclencheur | H31: Seuil | J31: Effet automatique | P31: Où le suivre
A32: Produit | C32: Contribution < 12 % du CA net ou < 8 CHF par commande | H32: =TEXT(Plancher_pct,"0%")&" / "&TEXT(Plancher_CHF,"0")&" CHF" -> 12% / 8 CHF | J32: Vente ou promotion bloquée | P32: Prix plancher l. 35 ; Scénarios l. 21
A33: Extension | C33: > 25 % du budget stock, ou 45 jours sans vente | H33: ='Budget initial'!C26 -> 750 | J33: Plus de réassort + proposition de démarque | P33: Budget initial l. 26
A34: Publicité | C34: CAC > contribution par commande sur 7 jours glissants, ou plafond journalier | H34: =INDEX(Scénarios!$B$18:$D$18,Scenario_choisi) -> 19.33395 | J34: Campagne coupée | P34: Scénarios l. 26 ; tableau de bord acquisition
A35: Cash | C35: Cash disponible (solde − précommandes) < réserve | H35: =Reserve_cash -> 1600 | J35: Plus d'achat ni de publicité | P35: tresorerie_13_semaines.xlsx l. 49 à 51
A36: Global | C36: Perte cumulée ≥ 20 % du capital engagé | H36: =-Perte_max -> -1600 | J36: TOUT gelé, retour au niveau d'autonomie 1, alerte ; réarmement par la propriétaire | P36: Cette feuille, colonne Y
A37: Temps | C37: 60 jours sans atteindre les seuils de validation | H37: =Jours_validation&" jours" -> 60 jours | J37: Dossier continuer / ajuster / arrêter | P37: Cette feuille, lignes 25 à 28
B39: ="PROJECTION — scénario "&E6&" (formules, ne pas saisir)" -> PROJECTION — scénario Central (formules, ne pas saisir) | M39: RÉEL — à saisir chaque lundi (CHF HT, coûts en positif) | U39: RÉEL — calculé | Z39: Aides de calcul
A40: Semaine | B40: Commandes | C40: Ventes nettes HT | D40: Coût historique | E40: Paiement | F40: Logistique nette | G40: SAV | H40: Acquisition | I40: Contribution après pub | J40: Charges fixes | K40: Contribution nette | L40: Cumul projeté | M40: Commandes payées | N40: Ventes nettes HT | O40: Coût historique | P40: Paiement | Q40: Logistique nette | R40: SAV | S40: Acquisition | T40: Charges fixes | U40: Contribution après pub | V40: Contribution nette | W40: CUMUL RÉEL (étoile polaire) | X40: Écart cumul réel − projeté | Y40: Statut stop-loss global | Z40: aide : reprise projetée | AA40: aide : gel projeté | AB40: aide : reprise réelle | AC40: aide : gel réel
A41: 1 | B41: =IF(A41>=Semaine_ouverture,$E$9,0) -> 0 | C41: =B41*Panier_HT -> 0 | D41: =C41*Cout_produit_pct -> 0 | E41: =B41*(Frais_paiement_pct*Panier_TTC+Frais_paiement_fixe) -> 0 | F41: =B41*$E$12 -> 0 | G41: =B41*Provision_SAV -> 0 | H41: =B41*$E$8 -> 0 | I41: =C41-D41-E41-F41-G41-H41 -> 0 | J41: =$E$11 -> 92.307692 | K41: =I41-J41 -> -92.307692 | L41: =SUM($K$41:K41) -> -92.307692 | U41: =IF(COUNT(M41:T41)=0,"",N41-O41-P41-Q41-R41-S41) | V41: =IF(COUNT(M41:T41)=0,"",U41-T41) | W41: =IF(V41="","",SUM($V$41:V41)) | X41: =IF(W41="","",W41-L41) | Y41: =IF(W41="","",IF(MIN($W$41:W41)<=-Perte_max,"GEL GLOBAL",IF(V41<0,"semaine négative","OK"))) | Z41: =IF(AND(A41>$E$21,L41>0),A41,"") | AA41: =IF(L41<=-Perte_max,A41,"") | AB41: =IF(W41="","",IF(AND(A41>$F$21,W41>0),A41,"")) | AC41: =IF(W41="","",IF(W41<=-Perte_max,A41,""))
A42: 2 | B42: =IF(A42>=Semaine_ouverture,$E$9,0) -> 0 | C42: =B42*Panier_HT -> 0 | D42: =C42*Cout_produit_pct -> 0 | E42: =B42*(Frais_paiement_pct*Panier_TTC+Frais_paiement_fixe) -> 0 | F42: =B42*$E$12 -> 0 | G42: =B42*Provision_SAV -> 0 | H42: =B42*$E$8 -> 0 | I42: =C42-D42-E42-F42-G42-H42 -> 0 | J42: =$E$11 -> 92.307692 | K42: =I42-J42 -> -92.307692 | L42: =SUM($K$41:K42) -> -184.61538 | U42: =IF(COUNT(M42:T42)=0,"",N42-O42-P42-Q42-R42-S42) | V42: =IF(COUNT(M42:T42)=0,"",U42-T42) | W42: =IF(V42="","",SUM($V$41:V42)) | X42: =IF(W42="","",W42-L42) | Y42: =IF(W42="","",IF(MIN($W$41:W42)<=-Perte_max,"GEL GLOBAL",IF(V42<0,"semaine négative","OK"))) | Z42: =IF(AND(A42>$E$21,L42>0),A42,"") | AA42: =IF(L42<=-Perte_max,A42,"") | AB42: =IF(W42="","",IF(AND(A42>$F$21,W42>0),A42,"")) | AC42: =IF(W42="","",IF(W42<=-Perte_max,A42,""))
A43: 3 | B43: =IF(A43>=Semaine_ouverture,$E$9,0) -> 0 | C43: =B43*Panier_HT -> 0 | D43: =C43*Cout_produit_pct -> 0 | E43: =B43*(Frais_paiement_pct*Panier_TTC+Frais_paiement_fixe) -> 0 | F43: =B43*$E$12 -> 0 | G43: =B43*Provision_SAV -> 0 | H43: =B43*$E$8 -> 0 | I43: =C43-D43-E43-F43-G43-H43 -> 0 | J43: =$E$11 -> 92.307692 | K43: =I43-J43 -> -92.307692 | L43: =SUM($K$41:K43) -> -276.92308 | U43: =IF(COUNT(M43:T43)=0,"",N43-O43-P43-Q43-R43-S43) | V43: =IF(COUNT(M43:T43)=0,"",U43-T43) | W43: =IF(V43="","",SUM($V$41:V43)) | X43: =IF(W43="","",W43-L43) | Y43: =IF(W43="","",IF(MIN($W$41:W43)<=-Perte_max,"GEL GLOBAL",IF(V43<0,"semaine négative","OK"))) | Z43: =IF(AND(A43>$E$21,L43>0),A43,"") | AA43: =IF(L43<=-Perte_max,A43,"") | AB43: =IF(W43="","",IF(AND(A43>$F$21,W43>0),A43,"")) | AC43: =IF(W43="","",IF(W43<=-Perte_max,A43,""))
A44: 4 | B44: =IF(A44>=Semaine_ouverture,$E$9,0) -> 0 | C44: =B44*Panier_HT -> 0 | D44: =C44*Cout_produit_pct -> 0 | E44: =B44*(Frais_paiement_pct*Panier_TTC+Frais_paiement_fixe) -> 0 | F44: =B44*$E$12 -> 0 | G44: =B44*Provision_SAV -> 0 | H44: =B44*$E$8 -> 0 | I44: =C44-D44-E44-F44-G44-H44 -> 0 | J44: =$E$11 -> 92.307692 | K44: =I44-J44 -> -92.307692 | L44: =SUM($K$41:K44) -> -369.23077 | U44: =IF(COUNT(M44:T44)=0,"",N44-O44-P44-Q44-R44-S44) | V44: =IF(COUNT(M44:T44)=0,"",U44-T44) | W44: =IF(V44="","",SUM($V$41:V44)) | X44: =IF(W44="","",W44-L44) | Y44: =IF(W44="","",IF(MIN($W$41:W44)<=-Perte_max,"GEL GLOBAL",IF(V44<0,"semaine négative","OK"))) | Z44: =IF(AND(A44>$E$21,L44>0),A44,"") | AA44: =IF(L44<=-Perte_max,A44,"") | AB44: =IF(W44="","",IF(AND(A44>$F$21,W44>0),A44,"")) | AC44: =IF(W44="","",IF(W44<=-Perte_max,A44,""))
...

Sheet Budget initial
A1: Budget initial — décaissement pilote (BP §3)
A2: Aucune offre prestataire confirmée. Remplacer chaque ligne par un devis avant engagement.
A4: Poste | B4: Budget pilote CHF | C4: Nature (BP) | D4: Traitement en trésorerie
A5: Stock acheté rendu Suisse | B5: 3000 | C5: Hypothèse de coût cash | D5: Achats de stock engagés
A6: Site et automatisation pilote | B6: 1500 | C6: Budget plafonné ; réalisation interne/assistée | D6: Dépenses de lancement
A7: DA et contenus de lancement | B7: 400 | C7: Dépenses cash hors temps interne | D7: Dépenses de lancement
A8: Administration et revue des documents | B8: 700 | C8: Provision à confirmer par devis | D8: Dépenses de lancement
A9: Emballages et matériel | B9: 300 | C9: Provision | D9: Dépenses de lancement
A10: Test acquisition | B10: 500 | C10: Plafond avant validation CAC | D10: Publicité (jours 46 à 60)
A11: Réserve de trésorerie | B11: 1600 | C11: Réassort, versements différés, remboursement | D11: Non décaissée
A12: Total | B12: =SUM(B5:B11) -> 8000
A13: Total publié dans le BP | B13: 8000
A14: Contrôle | B14: =IF(B12=B13,"OK — conforme BP","ÉCART "&TEXT(B12-B13,"#,##0")) -> OK — conforme BP
A15: Décaissé avant la première vente (hors réserve) | B15: =SUM(B5:B10) -> 6400
A16: Trésorerie conservée à l'ouverture (réserve) | B16: =B11 -> 1600 | C16: Attention : les charges fixes des mois sans ventes ne figurent pas dans ce budget (voir NOTE_VERIFICATION_BP.md).
A18: Répartition indicative du budget stock (BP §1) — suit les marges et allocations, pas un objectif de volume
A19: Catégorie | B19: Part du stock | C19: CHF | D19: Remarque
A20: Displays | B20: 0.25 | C20: =$B$5*B20 -> 750
A21: ETB | B21: 0.25 | C21: =$B$5*B21 -> 750
A22: Bundles et tripacks | B22: 0.2 | C22: =$B$5*B22 -> 600
A23: Coffrets | B23: 0.2 | C23: =$B$5*B23 -> 600
A24: Accessoires | B24: 0.1 | C24: =$B$5*B24 -> 300
A25: Total | B25: =SUM(B20:B24) -> 1 | C25: =SUM(C20:C24) -> 3000 | D25: =IF(ROUND(B25,4)=1,"OK — 100 %","ATTENTION : la répartition ne fait pas 100 %") -> OK — 100 %
A26: Plafond par extension au lancement | B26: 0.25 | C26: =$B$5*B26 -> 750 | D26: BP §1 — exceptions à documenter

Sheet Charges mensuelles
A1: Charges mensuelles de simulation (BP §3)
A2: Enveloppes, pas les tarifs actuels des logiciels ou prestataires. Hors publicité et rémunération.
A3: Poste | B3: CHF par mois | C3: Source / à remplacer par
A4: Site, apps, hébergement et automatisation | B4: 180 | C4: Abonnement boutique + apps + hébergement (devis)
A5: Comptabilité et administration | B5: 120 | C5: Offre fiduciaire
A6: Divers, assurance et petit stockage | B6: 100 | C6: Offres assurance RC / stockage
A7: Total fixe hors publicité et rémunération | B7: =SUM(B4:B6) -> 400
A8: Total publié dans le BP | B8: 400
A9: Contrôle | B9: =IF(B7=B8,"OK — conforme BP","ÉCART "&TEXT(B7-B8,"#,##0")) -> OK — conforme BP
A11: Temps de travail non rémunéré dans le résultat (BP §3 : le valoriser à part)
A12: Indicateur | B12: Heures par mois | C12: Calcul
A13: Supervision — minimum | B13: =Heures_min*Semaines_mois -> 26 | C13: 6 h/semaine × 52/12
A14: Supervision — maximum | B14: =Heures_max*Semaines_mois -> 43.333333 | C14: 10 h/semaine × 52/12
A15: Préparation des colis | C15: Voir feuille Scénarios (minutes par commande × commandes)

Sheet Scénarios
A1: Scénarios mensuels (BP §10)
A2: Entité assujettie, méthode effective. Aucun salaire, impôt, amortissement ni coût initial inclus. Valeurs exactes ; affichage arrondi.
A4: Indicateur (par mois) | B4: Prudent | C4: Central | D4: Développement | E4: Unité / formule
A5: Commandes payées | B5: =Hypothèses!B27 -> 40 | C5: =Hypothèses!C27 -> 100 | D5: =Hypothèses!D27 -> 200 | E5: Hypothèses
A6: Panier produits TTC | B6: =Panier_TTC -> 95 | C6: =Panier_TTC -> 95 | D6: =Panier_TTC -> 95 | E6: CHF
A7: Panier produits HT | B7: =Panier_HT -> 87.881591 | C7: =Panier_HT -> 87.881591 | D7: =Panier_HT -> 87.881591 | E7: CHF = TTC / (1 + TVA)
A8: CA produits TTC | B8: =B5*B6 -> 3800 | C8: =C5*C6 -> 9500 | D8: =D5*D6 -> 19000 | E8: CHF
A9: CA produits HT | B9: =B8/(1+TVA) -> 3515.2636 | C9: =C8/(1+TVA) -> 8788.1591 | D9: =D8/(1+TVA) -> 17576.318 | E9: CHF
A10: TVA collectée (à reverser) | B10: =B8-B9 -> 284.73636 | C10: =C8-C9 -> 711.84089 | D10: =D8-D9 -> 1423.6818 | E10: CHF
A11: Contribution avant acquisition | B11: =B9*Taux_contribution -> 773.358 | C11: =C9*Taux_contribution -> 1933.395 | D11: =D9*Taux_contribution -> 3866.79 | E11: CHF = CA HT × 22 %
A12: CAC moyen | B12: =Hypothèses!B28 -> 8 | C12: =Hypothèses!C28 -> 6 | D12: =Hypothèses!D28 -> 5 | E12: CHF / commande
A13: Acquisition totale | B13: =B5*B12 -> 320 | C13: =C5*C12 -> 600 | D13: =D5*D12 -> 1000 | E13: CHF
A14: Charges fixes | B14: =Charges_fixes -> 400 | C14: =Charges_fixes -> 400 | D14: =Charges_fixes -> 400 | E14: CHF
A15: Résultat avant rémunération | B15: =B11-B13-B14 -> 53.358002 | C15: =C11-C13-C14 -> 933.395 | D15: =D11-D13-D14 -> 2466.79 | E15: CHF
A16: Rémunération budgétée | B16: =Remuneration -> 2000 | C16: =Remuneration -> 2000 | D16: =Remuneration -> 2000 | E16: CHF (hors cotisations)
A17: Résultat après rémunération | B17: =B15-B16 -> -1946.642 | C17: =C15-C16 -> -1066.605 | D17: =D15-D16 -> 466.79001 | E17: CHF
A18: Contribution / commande avant acquisition | B18: =B7*Taux_contribution -> 19.33395 | C18: =C7*Taux_contribution -> 19.33395 | D18: =D7*Taux_contribution -> 19.33395 | E18: CHF
A19: Contribution / commande après CAC | B19: =B18-B12 -> 11.33395 | C19: =C18-C12 -> 13.33395 | D19: =D18-D12 -> 14.33395 | E19: CHF
A20: Contribution après CAC en % du CA HT | B20: =IF(B7>0,B19/B7,0) -> 0.12896842 | C20: =IF(C7>0,C19/C7,0) -> 0.15172632 | D20: =IF(D7>0,D19/D7,0) -> 0.16310526 | E20: %
A21: Plancher dur BP §5 respecté ? (≥ 8 CHF et ≥ 12 %) | B21: =IF(AND(B19>=Plancher_CHF,B20>=Plancher_pct),"oui","NON") -> oui | C21: =IF(AND(C19>=Plancher_CHF,C20>=Plancher_pct),"oui","NON") -> oui | D21: =IF(AND(D19>=Plancher_CHF,D20>=Plancher_pct),"oui","NON") -> oui | E21: BP §5
A22: CA TTC annualisé | B22: =B8*12 -> 45600 | C22: =C8*12 -> 114000 | D22: =D8*12 -> 228000 | E22: CHF/an
A23: Seuil TVA 100 000 CHF atteint ? | B23: =IF(B22>=Seuil_TVA,"OUI — anticiper l'examen TVA","non") -> non | C23: =IF(C22>=Seuil_TVA,"OUI — anticiper l'examen TVA","non") -> OUI — anticiper l'examen TVA | D23: =IF(D22>=Seuil_TVA,"OUI — anticiper l'examen TVA","non") -> OUI — anticiper l'examen TVA | E23: BP §4, §10
A24: Heures de travail / mois (supervision moyenne + colis) | B24: =(Heures_min+Heures_max)/2*Semaines_mois+B5*Minutes_prep/60 -> 44.666667 | C24: =(Heures_min+Heures_max)/2*Semaines_mois+C5*Minutes_prep/60 -> 59.666667 | D24: =(Heures_min+Heures_max)/2*Semaines_mois+D5*Minutes_prep/60 -> 84.666667 | E24: h
A25: Rémunération implicite du travail | B25: =IF(B24>0,B15/B24,0) -> 1.1945821 | C25: =IF(C24>0,C15/C24,0) -> 15.643492 | D25: =IF(D24>0,D15/D24,0) -> 29.135315 | E25: CHF/h, avant impôts et charges sociales
A26: Stop-loss pub : CAC > contribution / commande ? | B26: =IF(B12>B18,"OUI — campagne coupée","non") -> non | C26: =IF(C12>C18,"OUI — campagne coupée","non") -> non | D26: =IF(D12>D18,"OUI — campagne coupée","non") -> non | E26: Mandat (7 jours glissants en exploitation)
A27: Contrôle vs valeurs publiées au BP §10 (arrondies au franc)
A28: Valeur BP | B28: Prudent | C28: Central | D28: Développement | E28: Écart = arrondi(recalcul) − BP
A29: CA produits TTC | B29: 3800 | C29: 9500 | D29: 19000
A30: CA produits HT | B30: 3515 | C30: 8788 | D30: 17577
A31: Contribution avant acquisition | B31: 773 | C31: 1933 | D31: 3867
A32: Acquisition totale | B32: 320 | C32: 600 | D32: 1000
A33: Résultat avant rémunération | B33: 53 | C33: 933 | D33: 2467
A35: Écart (CHF) | B35: Prudent | C35: Central | D35: Développement | E35: Commentaire
A36: Écart CA produits TTC | B36: =ROUND(B8,0)-B29 -> 0 | C36: =ROUND(C8,0)-C29 -> 0 | D36: =ROUND(D8,0)-D29 -> 0
A37: Écart CA produits HT | B37: =ROUND(B9,0)-B30 -> 0 | C37: =ROUND(C9,0)-C30 -> 0 | D37: =ROUND(D9,0)-D30 -> -1 | E37: Développement : 19 000 / 1,081 = 17 576,32 ⇒ 17 576 (BP 17 577, sans effet sur la suite)
A38: Écart Contribution avant acquisition | B38: =ROUND(B11,0)-B31 -> 0 | C38: =ROUND(C11,0)-C31 -> 0 | D38: =ROUND(D11,0)-D31 -> 0
A39: Écart Acquisition totale | B39: =ROUND(B13,0)-B32 -> 0 | C39: =ROUND(C13,0)-C32 -> 0 | D39: =ROUND(D13,0)-D32 -> 0
A40: Écart Résultat avant rémunération | B40: =ROUND(B15,0)-B33 -> 0 | C40: =ROUND(C15,0)-C33 -> 0 | D40: =ROUND(D15,0)-D33 -> 0
A41: Statut | B41: =IF(SUMPRODUCT(ABS(B36:B40))=0,"OK","ÉCART "&SUMPRODUCT(B36:B40)&" CHF") -> OK | C41: =IF(SUMPRODUCT(ABS(C36:C40))=0,"OK","ÉCART "&SUMPRODUCT(C36:C40)&" CHF") -> OK | D41: =IF(SUMPRODUCT(ABS(D36:D40))=0,"OK","ÉCART "&SUMPRODUCT(D36:D40)&" CHF") -> ÉCART -1 CHF

Sheet Seuil & sensibilité
A1: Seuil de rentabilité et sensibilité (BP §10)
A2: Seuil = charges à couvrir / contribution par commande après CAC, arrondi au-dessus. Le BP arrondit la contribution au centime avant de diviser.
A4: Seuil de rentabilité — scénario central
A5: Indicateur | B5: Calcul exact | C5: Méthode BP (centime) | D5: Valeur BP | E5: Statut | F5: Commentaire
A6: Contribution / commande avant acquisition | B6: =Panier_HT*Taux_contribution -> 19.33395 | C6: =ROUND(B6,2) -> 19.33 | D6: 19.33 | E6: =IF(C6=D6,IF(ROUND(B6,2)=D6,"OK","OK méthode BP — exact : "&ROUND(B6,2)),"ÉCART") -> OK
A7: CAC moyen (central) | B7: =Hypothèses!C28 -> 6 | C7: =B7 -> 6 | D7: 6
A8: Contribution / commande après CAC | B8: =B6-B7 -> 13.33395 | C8: =ROUND(C6-C7,2) -> 13.33 | D8: 13.33 | E8: =IF(C8=D8,IF(ROUND(B8,2)=D8,"OK","OK méthode BP — exact : "&ROUND(B8,2)),"ÉCART") -> OK
A9: Charges fixes à couvrir | B9: =Charges_fixes -> 400 | C9: =Charges_fixes -> 400 | D9: 400
A10: Seuil en commandes (décimal) | B10: =B9/B8 -> 29.998612 | C10: =C9/C8 -> 30.007502
A11: Seuil cash d'exploitation (commandes/mois) | B11: =ROUNDUP(B10,0) -> 30 | C11: =ROUNDUP(C10,0) -> 31 | D11: 31 | E11: =IF(C11=D11,IF(ROUND(B11,2)=D11,"OK","OK méthode BP — exact : "&ROUND(B11,2)),"ÉCART") -> OK méthode BP — exact : 30 | F11: Exact 29,99 ⇒ 30 commandes, mais 30 × 13,334 ne dépasse 400 que de 0,02 CHF : garder 31.
A12: Surplus au seuil (CHF) | B12: =B11*B8-B9 -> 0.018501388 | C12: =C11*C8-C9 -> 13.23
A13: Seuil avec rémunération budgétée (commandes/mois) | B13: =ROUNDUP((B9+Remuneration)/B8,0) -> 180 | C13: =ROUNDUP((C9+Remuneration)/C8,0) -> 181 | D13: 181 | E13: =IF(C13=D13,IF(ROUND(B13,2)=D13,"OK","OK méthode BP — exact : "&ROUND(B13,2)),"ÉCART") -> OK méthode BP — exact : 180 | F13: Hors cotisations sociales et coûts de la rémunération (à ajouter).
A15: Sensibilité publiée au BP §10
A16: Cas | B16: Contribution / commande | C16: Après CAC | D16: Seuil (commandes) | E16: Valeur BP (seuil) | F16: Plancher dur 8 CHF/commande (BP §5) ?
A17: Contribution 15 %, CAC central | B17: =Panier_HT*Taux_sensibilite -> 13.182239 | C17: =B17-Hypothèses!C28 -> 7.1822387 | D17: =IF(C17>0,ROUNDUP(Charges_fixes/C17,0),"non rentable") -> 56 | E17: 56 | F17: =IF(C17>=Plancher_CHF,"respecté","NON — sous le plancher dur") -> NON — sous le plancher dur
A18: Contribution 22 %, CAC élevé | B18: =Panier_HT*Taux_contribution -> 19.33395 | C18: =B18-CAC_eleve -> 4.33395 | D18: =IF(C18>0,ROUNDUP(Charges_fixes/C18,0),"non rentable") -> 93 | E18: 93 | F18: =IF(C18>=Plancher_CHF,"respecté","NON — sous le plancher dur") -> NON — sous le plancher dur
A19: Valeurs BP par commande | B19: 13,18 / 22 % : 19,33 | C19: 7,18 / 4,33
A21: Seuil (commandes/mois) — charges fixes seules ; orange = contribution après CAC sous le plancher dur de 8 CHF
A22: Contribution ↓ / CAC (CHF) → | B22: 0 | C22: 4 | D22: 5 | E22: 6 | F22: 8 | G22: 10 | H22: 12 | I22: 15
A23: 0.12 | B23: =IF((Panier_HT*$A23-B$22)>0,ROUNDUP(Charges_fixes/(Panier_HT*$A23-B$22),0),"non rentable") -> 38 | C23: =IF((Panier_HT*$A23-C$22)>0,ROUNDUP(Charges_fixes/(Panier_HT*$A23-C$22),0),"non rentable") -> 62 | D23: =IF((Panier_HT*$A23-D$22)>0,ROUNDUP(Charges_fixes/(Panier_HT*$A23-D$22),0),"non rentable") -> 73 | E23: =IF((Panier_HT*$A23-E$22)>0,ROUNDUP(Charges_fixes/(Panier_HT*$A23-E$22),0),"non rentable") -> 88 | F23: =IF((Panier_HT*$A23-F$22)>0,ROUNDUP(Charges_fixes/(Panier_HT*$A23-F$22),0),"non rentable") -> 158 | G23: =IF((Panier_HT*$A23-G$22)>0,ROUNDUP(Charges_fixes/(Panier_HT*$A23-G$22),0),"non rentable") -> 733 | H23: =IF((Panier_HT*$A23-H$22)>0,ROUNDUP(Charges_fixes/(Panier_HT*$A23-H$22),0),"non rentable") -> non rentable | I23: =IF((Panier_HT*$A23-I$22)>0,ROUNDUP(Charges_fixes/(Panier_HT*$A23-I$22),0),"non rentable") -> non rentable
A24: 0.14 | B24: =IF((Panier_HT*$A24-B$22)>0,ROUNDUP(Charges_fixes/(Panier_HT*$A24-B$22),0),"non rentable") -> 33 | C24: =IF((Panier_HT*$A24-C$22)>0,ROUNDUP(Charges_fixes/(Panier_HT*$A24-C$22),0),"non rentable") -> 49 | D24: =IF((Panier_HT*$A24-D$22)>0,ROUNDUP(Charges_fixes/(Panier_HT*$A24-D$22),0),"non rentable") -> 55 | E24: =IF((Panier_HT*$A24-E$22)>0,ROUNDUP(Charges_fixes/(Panier_HT*$A24-E$22),0),"non rentable") -> 64 | F24: =IF((Panier_HT*$A24-F$22)>0,ROUNDUP(Charges_fixes/(Panier_HT*$A24-F$22),0),"non rentable") -> 93 | G24: =IF((Panier_HT*$A24-G$22)>0,ROUNDUP(Charges_fixes/(Panier_HT*$A24-G$22),0),"non rentable") -> 174 | H24: =IF((Panier_HT*$A24-H$22)>0,ROUNDUP(Charges_fixes/(Panier_HT*$A24-H$22),0),"non rentable") -> 1319 | I24: =IF((Panier_HT*$A24-I$22)>0,ROUNDUP(Charges_fixes/(Panier_HT*$A24-I$22),0),"non rentable") -> non rentable
A25: 0.15 | B25: =IF((Panier_HT*$A25-B$22)>0,ROUNDUP(Charges_fixes/(Panier_HT*$A25-B$22),0),"non rentable") -> 31 | C25: =IF((Panier_HT*$A25-C$22)>0,ROUNDUP(Charges_fixes/(Panier_HT*$A25-C$22),0),"non rentable") -> 44 | D25: =IF((Panier_HT*$A25-D$22)>0,ROUNDUP(Charges_fixes/(Panier_HT*$A25-D$22),0),"non rentable") -> 49 | E25: =IF((Panier_HT*$A25-E$22)>0,ROUNDUP(Charges_fixes/(Panier_HT*$A25-E$22),0),"non rentable") -> 56 | F25: =IF((Panier_HT*$A25-F$22)>0,ROUNDUP(Charges_fixes/(Panier_HT*$A25-F$22),0),"non rentable") -> 78 | G25: =IF((Panier_HT*$A25-G$22)>0,ROUNDUP(Charges_fixes/(Panier_HT*$A25-G$22),0),"non rentable") -> 126 | H25: =IF((Panier_HT*$A25-H$22)>0,ROUNDUP(Charges_fixes/(Panier_HT*$A25-H$22),0),"non rentable") -> 339 | I25: =IF((Panier_HT*$A25-I$22)>0,ROUNDUP(Charges_fixes/(Panier_HT*$A25-I$22),0),"non rentable") -> non rentable
A26: 0.16 | B26: =IF((Panier_HT*$A26-B$22)>0,ROUNDUP(Charges_fixes/(Panier_HT*$A26-B$22),0),"non rentable") -> 29 | C26: =IF((Panier_HT*$A26-C$22)>0,ROUNDUP(Charges_fixes/(Panier_HT*$A26-C$22),0),"non rentable") -> 40 | D26: =IF((Panier_HT*$A26-D$22)>0,ROUNDUP(Charges_fixes/(Panier_HT*$A26-D$22),0),"non rentable") -> 45 | E26: =IF((Panier_HT*$A26-E$22)>0,ROUNDUP(Charges_fixes/(Panier_HT*$A26-E$22),0),"non rentable") -> 50 | F26: =IF((Panier_HT*$A26-F$22)>0,ROUNDUP(Charges_fixes/(Panier_HT*$A26-F$22),0),"non rentable") -> 66 | G26: =IF((Panier_HT*$A26-G$22)>0,ROUNDUP(Charges_fixes/(Panier_HT*$A26-G$22),0),"non rentable") -> 99 | H26: =IF((Panier_HT*$A26-H$22)>0,ROUNDUP(Charges_fixes/(Panier_HT*$A26-H$22),0),"non rentable") -> 195 | I26: =IF((Panier_HT*$A26-I$22)>0,ROUNDUP(Charges_fixes/(Panier_HT*$A26-I$22),0),"non rentable") -> non rentable
A27: 0.18 | B27: =IF((Panier_HT*$A27-B$22)>0,ROUNDUP(Charges_fixes/(Panier_HT*$A27-B$22),0),"non rentable") -> 26 | C27: =IF((Panier_HT*$A27-C$22)>0,ROUNDUP(Charges_fixes/(Panier_HT*$A27-C$22),0),"non rentable") -> 34 | D27: =IF((Panier_HT*$A27-D$22)>0,ROUNDUP(Charges_fixes/(Panier_HT*$A27-D$22),0),"non rentable") -> 37 | E27: =IF((Panier_HT*$A27-E$22)>0,ROUNDUP(Charges_fixes/(Panier_HT*$A27-E$22),0),"non rentable") -> 41 | F27: =IF((Panier_HT*$A27-F$22)>0,ROUNDUP(Charges_fixes/(Panier_HT*$A27-F$22),0),"non rentable") -> 52 | G27: =IF((Panier_HT*$A27-G$22)>0,ROUNDUP(Charges_fixes/(Panier_HT*$A27-G$22),0),"non rentable") -> 69 | H27: =IF((Panier_HT*$A27-H$22)>0,ROUNDUP(Charges_fixes/(Panier_HT*$A27-H$22),0),"non rentable") -> 105 | I27: =IF((Panier_HT*$A27-I$22)>0,ROUNDUP(Charges_fixes/(Panier_HT*$A27-I$22),0),"non rentable") -> 489
A28: 0.2 | B28: =IF((Panier_HT*$A28-B$22)>0,ROUNDUP(Charges_fixes/(Panier_HT*$A28-B$22),0),"non rentable") -> 23 | C28: =IF((Panier_HT*$A28-C$22)>0,ROUNDUP(Charges_fixes/(Panier_HT*$A28-C$22),0),"non rentable") -> 30 | D28: =IF((Panier_HT*$A28-D$22)>0,ROUNDUP(Charges_fixes/(Panier_HT*$A28-D$22),0),"non rentable") -> 32 | E28: =IF((Panier_HT*$A28-E$22)>0,ROUNDUP(Charges_fixes/(Panier_HT*$A28-E$22),0),"non rentable") -> 35 | F28: =IF((Panier_HT*$A28-F$22)>0,ROUNDUP(Charges_fixes/(Panier_HT*$A28-F$22),0),"non rentable") -> 42 | G28: =IF((Panier_HT*$A28-G$22)>0,ROUNDUP(Charges_fixes/(Panier_HT*$A28-G$22),0),"non rentable") -> 53 | H28: =IF((Panier_HT*$A28-H$22)>0,ROUNDUP(Charges_fixes/(Panier_HT*$A28-H$22),0),"non rentable") -> 72 | I28: =IF((Panier_HT*$A28-I$22)>0,ROUNDUP(Charges_fixes/(Panier_HT*$A28-I$22),0),"non rentable") -> 156
A29: 0.22 | B29: =IF((Panier_HT*$A29-B$22)>0,ROUNDUP(Charges_fixes/(Panier_HT*$A29-B$22),0),"non rentable") -> 21 | C29: =IF((Panier_HT*$A29-C$22)>0,ROUNDUP(Charges_fixes/(Panier_HT*$A29-C$22),0),"non rentable") -> 27 | D29: =IF((Panier_HT*$A29-D$22)>0,ROUNDUP(Charges_fixes/(Panier_HT*$A29-D$22),0),"non rentable") -> 28 | E29: =IF((Panier_HT*$A29-E$22)>0,ROUNDUP(Charges_fixes/(Panier_HT*$A29-E$22),0),"non rentable") -> 30 | F29: =IF((Panier_HT*$A29-F$22)>0,ROUNDUP(Charges_fixes/(Panier_HT*$A29-F$22),0),"non rentable") -> 36 | G29: =IF((Panier_HT*$A29-G$22)>0,ROUNDUP(Charges_fixes/(Panier_HT*$A29-G$22),0),"non rentable") -> 43 | H29: =IF((Panier_HT*$A29-H$22)>0,ROUNDUP(Charges_fixes/(Panier_HT*$A29-H$22),0),"non rentable") -> 55 | I29: =IF((Panier_HT*$A29-I$22)>0,ROUNDUP(Charges_fixes/(Panier_HT*$A29-I$22),0),"non rentable") -> 93
A30: 0.24 | B30: =IF((Panier_HT*$A30-B$22)>0,ROUNDUP(Charges_fixes/(Panier_HT*$A30-B$22),0),"non rentable") -> 19 | C30: =IF((Panier_HT*$A30-C$22)>0,ROUNDUP(Charges_fixes/(Panier_HT*$A30-C$22),0),"non rentable") -> 24 | D30: =IF((Panier_HT*$A30-D$22)>0,ROUNDUP(Charges_fixes/(Panier_HT*$A30-D$22),0),"non rentable") -> 25 | E30: =IF((Panier_HT*$A30-E$22)>0,ROUNDUP(Charges_fixes/(Panier_HT*$A30-E$22),0),"non rentable") -> 27 | F30: =IF((Panier_HT*$A30-F$22)>0,ROUNDUP(Charges_fixes/(Panier_HT*$A30-F$22),0),"non rentable") -> 31 | G30: =IF((Panier_HT*$A30-G$22)>0,ROUNDUP(Charges_fixes/(Panier_HT*$A30-G$22),0),"non rentable") -> 37 | H30: =IF((Panier_HT*$A30-H$22)>0,ROUNDUP(Charges_fixes/(Panier_HT*$A30-H$22),0),"non rentable") -> 44 | I30: =IF((Panier_HT*$A30-I$22)>0,ROUNDUP(Charges_fixes/(Panier_HT*$A30-I$22),0),"non rentable") -> 66
A31: 0.26 | B31: =IF((Panier_HT*$A31-B$22)>0,ROUNDUP(Charges_fixes/(Panier_HT*$A31-B$22),0),"non rentable") -> 18 | C31: =IF((Panier_HT*$A31-C$22)>0,ROUNDUP(Charges_fixes/(Panier_HT*$A31-C$22),0),"non rentable") -> 22 | D31: =IF((Panier_HT*$A31-D$22)>0,ROUNDUP(Charges_fixes/(Panier_HT*$A31-D$22),0),"non rentable") -> 23 | E31: =IF((Panier_HT*$A31-E$22)>0,ROUNDUP(Charges_fixes/(Panier_HT*$A31-E$22),0),"non rentable") -> 24 | F31: =IF((Panier_HT*$A31-F$22)>0,ROUNDUP(Charges_fixes/(Panier_HT*$A31-F$22),0),"non rentable") -> 27 | G31: =IF((Panier_HT*$A31-G$22)>0,ROUNDUP(Charges_fixes/(Panier_HT*$A31-G$22),0),"non rentable") -> 32 | H31: =IF((Panier_HT*$A31-H$22)>0,ROUNDUP(Charges_fixes/(Panier_HT*$A31-H$22),0),"non rentable") -> 37 | I31: =IF((Panier_HT*$A31-I$22)>0,ROUNDUP(Charges_fixes/(Panier_HT*$A31-I$22),0),"non rentable") -> 51
A33: Seuil (commandes/mois) — charges fixes + rémunération budgétée
A34: Contribution ↓ / CAC (CHF) → | B34: 0 | C34: 4 | D34: 5 | E34: 6 | F34: 8 | G34: 10 | H34: 12 | I34: 15
A35: 0.12 | B35: =IF((Panier_HT*$A35-B$34)>0,ROUNDUP((Charges_fixes+Remuneration)/(Panier_HT*$A35-B$34),0),"non rentable") -> 228 | C35: =IF((Panier_HT*$A35-C$34)>0,ROUNDUP((Charges_fixes+Remuneration)/(Panier_HT*$A35-C$34),0),"non rentable") -> 367 | D35: =IF((Panier_HT*$A35-D$34)>0,ROUNDUP((Charges_fixes+Remuneration)/(Panier_HT*$A35-D$34),0),"non rentable") -> 433 | E35: =IF((Panier_HT*$A35-E$34)>0,ROUNDUP((Charges_fixes+Remuneration)/(Panier_HT*$A35-E$34),0),"non rentable") -> 528 | F35: =IF((Panier_HT*$A35-F$34)>0,ROUNDUP((Charges_fixes+Remuneration)/(Panier_HT*$A35-F$34),0),"non rentable") -> 943 | G35: =IF((Panier_HT*$A35-G$34)>0,ROUNDUP((Charges_fixes+Remuneration)/(Panier_HT*$A35-G$34),0),"non rentable") -> 4398 | H35: =IF((Panier_HT*$A35-H$34)>0,ROUNDUP((Charges_fixes+Remuneration)/(Panier_HT*$A35-H$34),0),"non rentable") -> non rentable | I35: =IF((Panier_HT*$A35-I$34)>0,ROUNDUP((Charges_fixes+Remuneration)/(Panier_HT*$A35-I$34),0),"non rentable") -> non rentable
A36: 0.14 | B36: =IF((Panier_HT*$A36-B$34)>0,ROUNDUP((Charges_fixes+Remuneration)/(Panier_HT*$A36-B$34),0),"non rentable") -> 196 | C36: =IF((Panier_HT*$A36-C$34)>0,ROUNDUP((Charges_fixes+Remuneration)/(Panier_HT*$A36-C$34),0),"non rentable") -> 290 | D36: =IF((Panier_HT*$A36-D$34)>0,ROUNDUP((Charges_fixes+Remuneration)/(Panier_HT*$A36-D$34),0),"non rentable") -> 329 | E36: =IF((Panier_HT*$A36-E$34)>0,ROUNDUP((Charges_fixes+Remuneration)/(Panier_HT*$A36-E$34),0),"non rentable") -> 381 | F36: =IF((Panier_HT*$A36-F$34)>0,ROUNDUP((Charges_fixes+Remuneration)/(Panier_HT*$A36-F$34),0),"non rentable") -> 558 | G36: =IF((Panier_HT*$A36-G$34)>0,ROUNDUP((Charges_fixes+Remuneration)/(Panier_HT*$A36-G$34),0),"non rentable") -> 1042 | H36: =IF((Panier_HT*$A36-H$34)>0,ROUNDUP((Charges_fixes+Remuneration)/(Panier_HT*$A36-H$34),0),"non rentable") -> 7910 | I36: =IF((Panier_HT*$A36-I$34)>0,ROUNDUP((Charges_fixes+Remuneration)/(Panier_HT*$A36-I$34),0),"non rentable") -> non rentable
A37: 0.15 | B37: =IF((Panier_HT*$A37-B$34)>0,ROUNDUP((Charges_fixes+Remuneration)/(Panier_HT*$A37-B$34),0),"non rentable") -> 183 | C37: =IF((Panier_HT*$A37-C$34)>0,ROUNDUP((Charges_fixes+Remuneration)/(Panier_HT*$A37-C$34),0),"non rentable") -> 262 | D37: =IF((Panier_HT*$A37-D$34)>0,ROUNDUP((Charges_fixes+Remuneration)/(Panier_HT*$A37-D$34),0),"non rentable") -> 294 | E37: =IF((Panier_HT*$A37-E$34)>0,ROUNDUP((Charges_fixes+Remuneration)/(Panier_HT*$A37-E$34),0),"non rentable") -> 335 | F37: =IF((Panier_HT*$A37-F$34)>0,ROUNDUP((Charges_fixes+Remuneration)/(Panier_HT*$A37-F$34),0),"non rentable") -> 464 | G37: =IF((Panier_HT*$A37-G$34)>0,ROUNDUP((Charges_fixes+Remuneration)/(Panier_HT*$A37-G$34),0),"non rentable") -> 755 | H37: =IF((Panier_HT*$A37-H$34)>0,ROUNDUP((Charges_fixes+Remuneration)/(Panier_HT*$A37-H$34),0),"non rentable") -> 2031 | I37: =IF((Panier_HT*$A37-I$34)>0,ROUNDUP((Charges_fixes+Remuneration)/(Panier_HT*$A37-I$34),0),"non rentable") -> non rentable
A38: 0.16 | B38: =IF((Panier_HT*$A38-B$34)>0,ROUNDUP((Charges_fixes+Remuneration)/(Panier_HT*$A38-B$34),0),"non rentable") -> 171 | C38: =IF((Panier_HT*$A38-C$34)>0,ROUNDUP((Charges_fixes+Remuneration)/(Panier_HT*$A38-C$34),0),"non rentable") -> 239 | D38: =IF((Panier_HT*$A38-D$34)>0,ROUNDUP((Charges_fixes+Remuneration)/(Panier_HT*$A38-D$34),0),"non rentable") -> 265 | E38: =IF((Panier_HT*$A38-E$34)>0,ROUNDUP((Charges_fixes+Remuneration)/(Panier_HT*$A38-E$34),0),"non rentable") -> 298 | F38: =IF((Panier_HT*$A38-F$34)>0,ROUNDUP((Charges_fixes+Remuneration)/(Panier_HT*$A38-F$34),0),"non rentable") -> 396 | G38: =IF((Panier_HT*$A38-G$34)>0,ROUNDUP((Charges_fixes+Remuneration)/(Panier_HT*$A38-G$34),0),"non rentable") -> 591 | H38: =IF((Panier_HT*$A38-H$34)>0,ROUNDUP((Charges_fixes+Remuneration)/(Panier_HT*$A38-H$34),0),"non rentable") -> 1165 | I38: =IF((Panier_HT*$A38-I$34)>0,ROUNDUP((Charges_fixes+Remuneration)/(Panier_HT*$A38-I$34),0),"non rentable") -> non rentable
A39: 0.18 | B39: =IF((Panier_HT*$A39-B$34)>0,ROUNDUP((Charges_fixes+Remuneration)/(Panier_HT*$A39-B$34),0),"non rentable") -> 152 | C39: =IF((Panier_HT*$A39-C$34)>0,ROUNDUP((Charges_fixes+Remuneration)/(Panier_HT*$A39-C$34),0),"non rentable") -> 204 | D39: =IF((Panier_HT*$A39-D$34)>0,ROUNDUP((Charges_fixes+Remuneration)/(Panier_HT*$A39-D$34),0),"non rentable") -> 222 | E39: =IF((Panier_HT*$A39-E$34)>0,ROUNDUP((Charges_fixes+Remuneration)/(Panier_HT*$A39-E$34),0),"non rentable") -> 245 | F39: =IF((Panier_HT*$A39-F$34)>0,ROUNDUP((Charges_fixes+Remuneration)/(Panier_HT*$A39-F$34),0),"non rentable") -> 307 | G39: =IF((Panier_HT*$A39-G$34)>0,ROUNDUP((Charges_fixes+Remuneration)/(Panier_HT*$A39-G$34),0),"non rentable") -> 413 | H39: =IF((Panier_HT*$A39-H$34)>0,ROUNDUP((Charges_fixes+Remuneration)/(Panier_HT*$A39-H$34),0),"non rentable") -> 629 | I39: =IF((Panier_HT*$A39-I$34)>0,ROUNDUP((Charges_fixes+Remuneration)/(Panier_HT*$A39-I$34),0),"non rentable") -> 2932
A40: 0.2 | B40: =IF((Panier_HT*$A40-B$34)>0,ROUNDUP((Charges_fixes+Remuneration)/(Panier_HT*$A40-B$34),0),"non rentable") -> 137 | C40: =IF((Panier_HT*$A40-C$34)>0,ROUNDUP((Charges_fixes+Remuneration)/(Panier_HT*$A40-C$34),0),"non rentable") -> 177 | D40: =IF((Panier_HT*$A40-D$34)>0,ROUNDUP((Charges_fixes+Remuneration)/(Panier_HT*$A40-D$34),0),"non rentable") -> 191 | E40: =IF((Panier_HT*$A40-E$34)>0,ROUNDUP((Charges_fixes+Remuneration)/(Panier_HT*$A40-E$34),0),"non rentable") -> 208 | F40: =IF((Panier_HT*$A40-F$34)>0,ROUNDUP((Charges_fixes+Remuneration)/(Panier_HT*$A40-F$34),0),"non rentable") -> 251 | G40: =IF((Panier_HT*$A40-G$34)>0,ROUNDUP((Charges_fixes+Remuneration)/(Panier_HT*$A40-G$34),0),"non rentable") -> 317 | H40: =IF((Panier_HT*$A40-H$34)>0,ROUNDUP((Charges_fixes+Remuneration)/(Panier_HT*$A40-H$34),0),"non rentable") -> 431 | I40: =IF((Panier_HT*$A40-I$34)>0,ROUNDUP((Charges_fixes+Remuneration)/(Panier_HT*$A40-I$34),0),"non rentable") -> 932
A41: 0.22 | B41: =IF((Panier_HT*$A41-B$34)>0,ROUNDUP((Charges_fixes+Remuneration)/(Panier_HT*$A41-B$34),0),"non rentable") -> 125 | C41: =IF((Panier_HT*$A41-C$34)>0,ROUNDUP((Charges_fixes+Remuneration)/(Panier_HT*$A41-C$34),0),"non rentable") -> 157 | D41: =IF((Panier_HT*$A41-D$34)>0,ROUNDUP((Charges_fixes+Remuneration)/(Panier_HT*$A41-D$34),0),"non rentable") -> 168 | E41: =IF((Panier_HT*$A41-E$34)>0,ROUNDUP((Charges_fixes+Remuneration)/(Panier_HT*$A41-E$34),0),"non rentable") -> 180 | F41: =IF((Panier_HT*$A41-F$34)>0,ROUNDUP((Charges_fixes+Remuneration)/(Panier_HT*$A41-F$34),0),"non rentable") -> 212 | G41: =IF((Panier_HT*$A41-G$34)>0,ROUNDUP((Charges_fixes+Remuneration)/(Panier_HT*$A41-G$34),0),"non rentable") -> 258 | H41: =IF((Panier_HT*$A41-H$34)>0,ROUNDUP((Charges_fixes+Remuneration)/(Panier_HT*$A41-H$34),0),"non rentable") -> 328 | I41: =IF((Panier_HT*$A41-I$34)>0,ROUNDUP((Charges_fixes+Remuneration)/(Panier_HT*$A41-I$34),0),"non rentable") -> 554
A42: 0.24 | B42: =IF((Panier_HT*$A42-B$34)>0,ROUNDUP((Charges_fixes+Remuneration)/(Panier_HT*$A42-B$34),0),"non rentable") -> 114 | C42: =IF((Panier_HT*$A42-C$34)>0,ROUNDUP((Charges_fixes+Remuneration)/(Panier_HT*$A42-C$34),0),"non rentable") -> 141 | D42: =IF((Panier_HT*$A42-D$34)>0,ROUNDUP((Charges_fixes+Remuneration)/(Panier_HT*$A42-D$34),0),"non rentable") -> 150 | E42: =IF((Panier_HT*$A42-E$34)>0,ROUNDUP((Charges_fixes+Remuneration)/(Panier_HT*$A42-E$34),0),"non rentable") -> 160 | F42: =IF((Panier_HT*$A42-F$34)>0,ROUNDUP((Charges_fixes+Remuneration)/(Panier_HT*$A42-F$34),0),"non rentable") -> 184 | G42: =IF((Panier_HT*$A42-G$34)>0,ROUNDUP((Charges_fixes+Remuneration)/(Panier_HT*$A42-G$34),0),"non rentable") -> 217 | H42: =IF((Panier_HT*$A42-H$34)>0,ROUNDUP((Charges_fixes+Remuneration)/(Panier_HT*$A42-H$34),0),"non rentable") -> 264 | I42: =IF((Panier_HT*$A42-I$34)>0,ROUNDUP((Charges_fixes+Remuneration)/(Panier_HT*$A42-I$34),0),"non rentable") -> 394
A43: 0.26 | B43: =IF((Panier_HT*$A43-B$34)>0,ROUNDUP((Charges_fixes+Remuneration)/(Panier_HT*$A43-B$34),0),"non rentable") -> 106 | C43: =IF((Panier_HT*$A43-C$34)>0,ROUNDUP((Charges_fixes+Remuneration)/(Panier_HT*$A43-C$34),0),"non rentable") -> 128 | D43: =IF((Panier_HT*$A43-D$34)>0,ROUNDUP((Charges_fixes+Remuneration)/(Panier_HT*$A43-D$34),0),"non rentable") -> 135 | E43: =IF((Panier_HT*$A43-E$34)>0,ROUNDUP((Charges_fixes+Remuneration)/(Panier_HT*$A43-E$34),0),"non rentable") -> 143 | F43: =IF((Panier_HT*$A43-F$34)>0,ROUNDUP((Charges_fixes+Remuneration)/(Panier_HT*$A43-F$34),0),"non rentable") -> 162 | G43: =IF((Panier_HT*$A43-G$34)>0,ROUNDUP((Charges_fixes+Remuneration)/(Panier_HT*$A43-G$34),0),"non rentable") -> 187 | H43: =IF((Panier_HT*$A43-H$34)>0,ROUNDUP((Charges_fixes+Remuneration)/(Panier_HT*$A43-H$34),0),"non rentable") -> 222 | I43: =IF((Panier_HT*$A43-I$34)>0,ROUNDUP((Charges_fixes+Remuneration)/(Panier_HT*$A43-I$34),0),"non rentable") -> 306

Sheet Prix plancher
A1: Prix plancher et contrôle de contribution (BP §4)
A2: P = (C + b + L + R + A) / ((1 − m) / (1 + t) − r). Exemple FICTIF du BP : aucun coût n'est un devis.
A4: Paramètre | B4: Cas 1 — assujetti (méthode effective) | C4: Cas 2 — non assujetti (t = 0) | D4: Unité | E4: Source
A5: Achat net hors TVA récupérable | B5: 140 | C5: =B5 -> 140 | D5: CHF | E5: BP §4 — exemple fictif
A6: TVA non récupérable incluse dans C | B6: 0 | C6: =TVA -> 0.081 | D6: % | E6: Cas 2 : 8,1 % non récupérables
A7: Coût rendu C | B7: =B5*(1+B6) -> 140 | C7: =C5*(1+C6) -> 151.34 | D7: CHF | E7: BP §4 (151,34 dans le cas 2)
A8: Frais de paiement proportionnels r | B8: 0.025 | C8: =B8 -> 0.025 | D8: % du TTC | E8: BP §4
A9: Frais fixes de paiement b | B9: 0.3 | C9: =B9 -> 0.3 | D9: CHF | E9: BP §4
A10: Préparation/expédition supportée L | B10: 3 | C10: =B10 -> 3 | D10: CHF | E10: BP §4
A11: Provision SAV R | B11: 1 | C11: =B11 -> 1 | D11: CHF | E11: BP §4
A12: Acquisition attribuée A | B12: 5 | C12: =B12 -> 5 | D12: CHF | E12: BP §4
A13: Contribution cible m | B13: 0.2 | C13: =B13 -> 0.2 | D13: % CA net | E13: BP §4-§5
A14: TVA sur ventes t | B14: =TVA -> 0.081 | C14: 0 | D14: % | E14: BP §4
A15: Numérateur C + b + L + R + A | B15: =B7+B9+B10+B11+B12 -> 149.3 | C15: =C7+C9+C10+C11+C12 -> 160.64
A16: Dénominateur (1 − m)/(1 + t) − r | B16: =(1-B13)/(1+B14)-B8 -> 0.7150555 | C16: =(1-C13)/(1+C14)-C8 -> 0.775
A17: Prix plancher P (exact) | B17: =IF(B16>0,B15/B16,"dénominateur ≤ 0 : marge impossible") -> 208.79498 | C17: =IF(C16>0,C15/C16,"dénominateur ≤ 0 : marge impossible") -> 207.27742
A18: Prix plancher arrondi au centime | B18: =ROUND(B17,2) -> 208.79 | C18: =ROUND(C17,2) -> 207.28
A19: Lecture BP — pas d'arrondi du prix public | B19: 10 | C19: =B19 -> 10
A20: Lecture BP — terminaison du prix public | B20: 9.9 | C20: =B20 -> 9.9
A21: Prix public — lecture BP (pas 10 / 9,90), différente du moteur v1 | B21: =ROUNDUP((B17-B20)/B19,0)*B19+B20 -> 209.9 | C21: =ROUNDUP((C17-C20)/C19,0)*C19+C20 -> 209.9 | E21: Concorde avec le moteur sur le cas BP seulement (coût 50 : 89,90 ici, 83,90 moteur)
A22: Lecture alternative « prochain X,90 » (pas de 1 CHF) | B22: =ROUNDUP((B17-0.9)/1,0)*1+0.9 -> 208.9 | C22: =ROUNDUP((C17-0.9)/1,0)*1+0.9 -> 207.9 | E22: Lectures du BP ; règle appliquée par le moteur : ligne 26
A23: Valeur BP — prix plancher | B23: 208.79 | C23: 207.28
A24: Valeur BP — prix public arrondi | B24: 209.9 | C24: n.c.
A25: Statut | B25: =IF(AND(B18=B23,ROUND(B21,2)=B24,ROUND(B26,2)=B24),"OK — conforme BP","ÉCART") -> OK — conforme BP | C25: =IF(C18=C23,"OK — conforme BP","ÉCART") -> OK — conforme BP
A26: Prix public moteur v1 (grille rounding_tiers, prix rentable ≥ 8 CHF par commande) | B26: =IF(ISNUMBER(B17),IF(ROUND(MAX(B17,(B7+B9+B10+B11+B12+Plancher_CHF)/(1/(1+B14)-B8)),6)<10,IF(MIN(-INT(-((ROUND(MAX(B17,(B7+B9+B10+B11+B12+Plancher_CHF)/(1/(1+B14)-B8)),6))-0.5)/1)*1+0.5,-INT(-((ROUND(MAX(B17,(B7+B9+B10+B11+B12+Plancher_CHF)/(1/(1+B14)-B8)),6))-0.9)/1)*1+0.9)<10,MIN(-INT(-((ROUND(MAX(B17,(B7+B9+B10+B11+B12+Plancher_CHF)/(1/(1+B14)-B8)),6))-0.5)/1)*1+0.5,-INT(-((ROUND(MAX(B17,(B7+B9+B10+B11+B12+Plancher_CHF)/(1/(1+B14)-B8)),6))-0.9)/1)*1+0.9),10.9),IF(ROUND(MAX(B17,(B7+B9+B10+B11+B12+Plancher_CHF)/(1/(1+B14)-B8)),6)<100,IF(-INT(-((ROUND(MAX(B17,(B7+B9+B10+B11+B12+Plancher_CHF)/(1/(1+B14)-B8)),6))-0.9)/1)*1+0.9<100,-INT(-((ROUND(MAX(B17,(B7+B9+B10+B11+B12+Plancher_CHF)/(1/(1+B14)-B8)),6))-0.9)/1)*1+0.9,104.9),MIN(-INT(-((ROUND(MAX(B17,(B7+B9+B10+B11+B12+Plancher_CHF)/(1/(1+B14)-B8)),6))-4.9)/10)*10+4.9,-INT(-((ROUND(MAX(B17,(B7+B9+B10+B11+B12+Plancher_CHF)/(1/(1+B14)-B8)),6))-9.9)/10)*10+9.9))),"n.c.") -> 209.9 | C26: =IF(ISNUMBER(C17),IF(ROUND(MAX(C17,(C7+C9+C10+C11+C12+Plancher_CHF)/(1/(1+C14)-C8)),6)<10,IF(MIN(-INT(-((ROUND(MAX(C17,(C7+C9+C10+C11+C12+Plancher_CHF)/(1/(1+C14)-C8)),6))-0.5)/1)*1+0.5,-INT(-((ROUND(MAX(C17,(C7+C9+C10+C11+C12+Plancher_CHF)/(1/(1+C14)-C8)),6))-0.9)/1)*1+0.9)<10,MIN(-INT(-((ROUND(MAX(C17,(C7+C9+C10+C11+C12+Plancher_CHF)/(1/(1+C14)-C8)),6))-0.5)/1)*1+0.5,-INT(-((ROUND(MAX(C17,(C7+C9+C10+C11+C12+Plancher_CHF)/(1/(1+C14)-C8)),6))-0.9)/1)*1+0.9),10.9),IF(ROUND(MAX(C17,(C7+C9+C10+C11+C12+Plancher_CHF)/(1/(1+C14)-C8)),6)<100,IF(-INT(-((ROUND(MAX(C17,(C7+C9+C10+C11+C12+Plancher_CHF)/(1/(1+C14)-C8)),6))-0.9)/1)*1+0.9<100,-INT(-((ROUND(MAX(C17,(C7+C9+C10+C11+C12+Plancher_CHF)/(1/(1+C14)-C8)),6))-0.9)/1)*1+0.9,104.9),MIN(-INT(-((ROUND(MAX(C17,(C7+C9+C10+C11+C12+Plancher_CHF)/(1/(1+C14)-C8)),6))-4.9)/10)*10+4.9,-INT(-((ROUND(MAX(C17,(C7+C9+C10+C11+C12+Plancher_CHF)/(1/(1+C14)-C8)),6))-9.9)/10)*10+9.9))),"n.c.") -> 209.9 | D26: CHF | E26: pokeshop.pricing (fait foi) : config/pricing_rules.v1.yaml, avant revérification
A27: Contribution d'une vente unitaire à un prix donné (cas 1)
A28: Indicateur | B28: Prix testé | C28: Prix public arrondi | D28: BP à 199,90 | E28: Statut (prix testé)
A29: Prix public TTC | B29: 199.9 | C29: =B26 -> 209.9 | D29: 199.9
A30: Vente nette = P / (1 + t) | B30: =B29/(1+$B$14) -> 184.92137 | C30: =C29/(1+$B$14) -> 194.17206 | D30: 184.92 | E30: =IF(ROUND(B30,2)=D30,"OK","ÉCART") -> OK
A31: Frais de paiement = r × P + b | B31: =$B$8*B29+$B$9 -> 5.2975 | C31: =$B$8*C29+$B$9 -> 5.5475 | D31: 5.3 | E31: =IF(ROUND(B31,2)=D31,"OK","ÉCART") -> OK
A32: Contribution = net − C − paiement − L − R − A | B32: =B30-$B$7-B31-$B$10-$B$11-$B$12 -> 30.623869 | C32: =C30-$B$7-C31-$B$10-$B$11-$B$12 -> 39.624563 | D32: 30.62 | E32: =IF(ROUND(B32,2)=D32,"OK","ÉCART") -> OK
A33: Contribution en % du CA net | B33: =B32/B30 -> 0.16560481 | C33: =C32/C30 -> 0.20406933 | D33: 0.1656 | E33: =IF(ROUND(B33,4)=D33,"OK","ÉCART") -> OK
A34: Cible m atteinte ? | B34: =IF(B33>=$B$13,"oui","NON — sous la cible") -> NON — sous la cible | C34: =IF(C33>=$B$13,"oui","NON — sous la cible") -> oui
A35: Plancher dur BP §5 respecté (≥ 12 % et ≥ 8 CHF) ? | B35: =IF(AND(B33>=Plancher_pct,B32>=Plancher_CHF),"oui","NON — blocage") -> oui | C35: =IF(AND(C33>=Plancher_pct,C32>=Plancher_CHF),"oui","NON — blocage") -> oui

Sheet Stock & BFR
A1: Stock nécessaire et besoin en fonds de roulement (BP §10)
A2: Les délais du cycle cash sont des HYPOTHÈSES FICTIVES (feuille Hypothèses) à remplacer par les conditions réelles fournisseur et PSP.
A4: Stock consommé par mois
A5: Indicateur | B5: Prudent | C5: Central | D5: Développement | E5: Unité
A6: Commandes par mois | B6: =Hypothèses!B27 -> 40 | C6: =Hypothèses!C27 -> 100 | D6: =Hypothèses!D27 -> 200 | E6: commandes
A7: CA net HT | B7: =B6*Panier_HT -> 3515.2636 | C7: =C6*Panier_HT -> 8788.1591 | D7: =D6*Panier_HT -> 17576.318 | E7: CHF/mois
A8: Coût produit en % du CA net | B8: =Cout_produit_pct -> 0.7 | C8: =Cout_produit_pct -> 0.7 | D8: =Cout_produit_pct -> 0.7 | E8: %
A9: Achats consommés HT | B9: =B7*B8 -> 2460.6846 | C9: =C7*C8 -> 6151.7114 | D9: =D7*D8 -> 12303.423 | E9: CHF/mois
A10: Stock initial (budget BP §3) | B10: =Stock_initial -> 3000 | C10: =Stock_initial -> 3000 | D10: =Stock_initial -> 3000 | E10: CHF
A11: Part d'un mois couverte par le stock initial | B11: =IF(B9>0,B10/B9,0) -> 1.2191729 | C11: =IF(C9>0,C10/C9,0) -> 0.48766917 | D11: =IF(D9>0,D10/D9,0) -> 0.24383459 | E11: %
A12: Couverture du stock initial | B12: =B11*Jours_mois -> 36.575188 | C12: =C11*Jours_mois -> 14.630075 | D12: =D11*Jours_mois -> 7.3150376 | E12: jours de ventes
A13: Manque pour financer un mois d'achats | B13: =MAX(0,B9-B10) -> 0 | C13: =MAX(0,C9-C10) -> 3151.7114 | D13: =MAX(0,D9-D10) -> 9303.4228 | E13: CHF
A14: Valeurs BP (central) : CA net 8 788 ; achats 6 152 | C14: 6152 | D14: =IF(ROUND(C9,0)=C14,"OK — conforme BP","ÉCART") -> OK — conforme BP
A16: Besoin en fonds de roulement (BFR) d'exploitation
A17: Indicateur | B17: Prudent | C17: Central | D17: Développement | E17: Calcul
A18: Achats consommés par jour | B18: =B9/Jours_mois -> 82.022818 | C18: =C9/Jours_mois -> 205.05705 | D18: =D9/Jours_mois -> 410.11409 | E18: achats / jours par mois
A19: CA TTC encaissé par jour | B19: =B6*Panier_TTC/Jours_mois -> 126.66667 | C19: =C6*Panier_TTC/Jours_mois -> 316.66667 | D19: =D6*Panier_TTC/Jours_mois -> 633.33333 | E19: commandes × panier TTC / jours
A20: Stock immobilisé (prépaiement + jours de stock) | B20: =B18*(Delai_prepaiement+Jours_stock) -> 3609.004 | C20: =C18*(Delai_prepaiement+Jours_stock) -> 9022.51 | D20: =D18*(Delai_prepaiement+Jours_stock) -> 18045.02 | E20: achats/jour × (délai + jours de stock)
A21: Encaissements PSP en attente de versement | B21: =B19*Delai_PSP -> 886.66667 | C21: =C19*Delai_PSP -> 2216.6667 | D21: =D19*Delai_PSP -> 4433.3333 | E21: CA/jour × délai PSP
A22: Crédit fournisseur (ressource) | B22: =B18*Credit_fournisseur -> 0 | C22: =C18*Credit_fournisseur -> 0 | D22: =D18*Credit_fournisseur -> 0 | E22: achats/jour × jours de crédit
A23: BFR total | B23: =B20+B21-B22 -> 4495.6707 | C23: =C20+C21-C22 -> 11239.177 | D23: =D20+D21-D22 -> 22478.353 | E23: stock + PSP − crédit
A24: Trésorerie mobilisable au lancement (stock + réserve) | B24: =Stock_initial+'Budget initial'!B11 -> 4600 | C24: =Stock_initial+'Budget initial'!B11 -> 4600 | D24: =Stock_initial+'Budget initial'!B11 -> 4600 | E24: budget BP §3
A25: Écart à financer (BFR − mobilisable) | B25: =MAX(0,B23-B24) -> 0 | C25: =MAX(0,C23-C24) -> 6639.1767 | D25: =MAX(0,D23-D24) -> 17878.353 | E25: apport, réassort plus fréquent
A27: Non comptés (prudence) : TVA collectée conservée jusqu'au décompte, TVA d'achat/import préfinancée. À affiner avec la fiduciaire.
