Workbook

Sheet Mode d'emploi
A1: Comparateur d'offres fournisseurs — {{NOM_BOUTIQUE}}
A2: AUCUN PRIX RÉEL. Seules les lignes marquées FICTIF (fournisseurs FICTIF_FOURNISSEUR_A et _B, référence FICTIF_R00) sont remplies, pour montrer le calcul. Les supprimer avant usage réel.
A3: Source : BP du 4.10.2026, §1 (devis sur les mêmes références), §2 (demande commerciale), §4 (coût rendu et prix plancher), §5 (règles), §13 (même panier aux 3 fournisseurs FR).
A4: Paramètres de prix : config/pricing_rules.v1.yaml, version v1-2026-10-04 (hypothèses BP §4-5, à confirmer par devis).
A6: MODE D'EMPLOI
A7: 1. Paramètres : choisir le mode TVA de l'entité (B4) selon la décision de la fiduciaire (B10). Les autres valeurs viennent du fichier de règles : ne les modifier qu'en créant une nouvelle version.
A8: 2. Fournisseurs : une ligne par fournisseur. Saisir pays d'expédition, devise, taux de change vers CHF (source + date), TVA facturée par le fournisseur (0 si facture d'export HT) et son pays, port amont et frais fixes de la commande (en devise), frais de dédouanement (CHF). Une case vide = fournisseur INCOMPLET.
A9: 3. Offres : une ligne par couple (référence, fournisseur), à partir du devis écrit. Saisir unités par conditionnement, prix du conditionnement, HT ou TTC, remise du palier atteint pour la quantité commandée, quantité commandée (en conditionnements), MOQ, disponibilité, allocation ferme, et la référence marché (médiane du prix total livré, docs/01-marche/GRILLE_CONCURRENCE.csv).
A10: 4. Les colonnes grises se calculent seules : coût rendu C par unité (CHF), prix plancher, écart au marché, contribution au prix marché, statut, rang.
A11: 5. Classement : meilleur et 2e fournisseur par référence. Synthèse fournisseurs : couverture du panier, valeur de la commande, minimum de commande atteint.
A13: RÈGLES DE CALCUL (identiques au moteur pokeshop.pricing)
A14: C = achat HT unitaire en CHF + TVA fournisseur non récupérable + port et frais ventilés + dédouanement ventilé + TVA import (seulement si NOT_REGISTERED). La TVA fournisseur n'est récupérable que si elle est suisse ET l'entité assujettie (EFFECTIVE). Port, frais et dédouanement sont ventilés au prorata de la valeur HT des lignes du même fournisseur. Droits de douane = 0 (produits industriels, depuis le 1.1.2024).
... A26: - Valider le fournisseur retenu par référence (C08) ; le classement est une aide, pas une décision.

Sheet Paramètres
A1: Paramètres de calcul
A2: Source : config/pricing_rules.v1.yaml (v1-2026-10-04) — hypothèses BP §4-5, à confirmer.
A3: Paramètre | B3: Valeur | C3: Note
A4: Mode TVA de l'entité (EFFECTIVE / NOT_REGISTERED) | B4: EFFECTIVE | C4: Décision de la fiduciaire (B10). EFFECTIVE = hypothèse du BP §10.
A5: t — TVA sur ventes | B5: =IF(Paramètres!$B$4="EFFECTIVE",Paramètres!$B$13,0) -> 0.081 | C5: 0 si non assujetti (BP §4).
A6: r — frais de paiement proportionnels | B6: 0.025 | C6: Hypothèse BP §4 ; contrat PSP.
A7: b — frais fixes de paiement (CHF/commande) | B7: 0.3 | C7: Hypothèse BP §4.
A8: L — logistique nette (CHF/commande) | B8: 3 | C8: Hypothèse BP §4 ; devis transporteur.
A9: R — provision SAV (CHF/commande) | B9: 1 | C9: Hypothèse BP §4.
A10: A — acquisition attribuée (CHF/commande) | B10: 5 | C10: Hypothèse BP §4.
A11: m — contribution cible (% du CA net) | B11: 0.2 | C11: BP §5.
A12: Seuil « au-dessus du marché » | B12: 0.1 | C12: BP §5 : > 10 % ⇒ à revoir.
A13: Taux normal de TVA suisse | B13: 0.081 | C13: Au 4.10.2026 [S6] ; à confirmer.
A14: Taux de TVA à l'importation (estimation) | B14: 0.081 | C14: Estimation ; la base réelle se lit sur le décompte OFDF [S7].
A15: Plancher dur (% du CA net) | B15: 0.12 | C15: BP §5 = stop-loss produit.
A16: Plancher dur (CHF/commande) | B16: 8 | C16: BP §5 = stop-loss produit.
A17: Version des règles | B17: v1-2026-10-04 | C17: Recopiée dans chaque décision de prix.

Sheet Fournisseurs
A1: Fournisseurs — conditions communes à toutes les lignes d'un même fournisseur
A2: Aucune donnée réelle : les 6 fournisseurs du BP (et la piste hors BP) sont à compléter à réception des devis. Lignes orange = FICTIF.
A4: Fournisseur | B4: Pays d'expédition (ISO2) | C4: Devise | D4: Taux → CHF (CHF pour 1 unité) | E4: Source du taux | F4: Date du taux | G4: TVA facturée par le fournisseur (taux) | H4: Pays de cette TVA (ISO2) | I4: Incoterm | J4: Port amont total de la commande (devise) | K4: Frais fixes de commande (devise) | L4: Dédouanement / transitaire total (CHF) | M4: Minimum de commande (devise) | N4: Délai annoncé (jours ouvrés) | O4: Paiement | P4: Flux de données | Q4: Exemple de fichier reçu (O/N) | R4: Statut | S4: Fictif (O/N) | T4: Complet (calculé)
A5: Asmodee France | R5: non contacté | S5: N | T5: =IF(A5="","",IF(AND(B5<>"",C5<>"",D5<>"",E5<>"",F5<>"",G5<>"",H5<>"",J5<>"",K5<>"",L5<>""),1,0)) -> 0
A6: Matoo et Miao | R6: non contacté | S6: N | T6: =IF(A6="","",IF(AND(B6<>"",C6<>"",D6<>"",E6<>"",F6<>"",G6<>"",H6<>"",J6<>"",K6<>"",L6<>""),1,0)) -> 0
A7: TCG Distribution | R7: non contacté | S7: N | T7: =IF(A7="","",IF(AND(B7<>"",C7<>"",D7<>"",E7<>"",F7<>"",G7<>"",H7<>"",J7<>"",K7<>"",L7<>""),1,0)) -> 0
A8: OtakuWorld | R8: non contacté | S8: N | T8: =IF(A8="","",IF(AND(B8<>"",C8<>"",D8<>"",E8<>"",F8<>"",G8<>"",H8<>"",J8<>"",K8<>"",L8<>""),1,0)) -> 0
A9: CardCosmos | R9: non contacté | S9: N | T9: =IF(A9="","",IF(AND(B9<>"",C9<>"",D9<>"",E9<>"",F9<>"",G9<>"",H9<>"",J9<>"",K9<>"",L9<>""),1,0)) -> 0
A10: Carletto AG (hors BP) | R10: non contacté | S10: N | T10: =IF(A10="","",IF(AND(B10<>"",C10<>"",D10<>"",E10<>"",F10<>"",G10<>"",H10<>"",J10<>"",K10<>"",L10<>""),1,0)) -> 0
A11: FICTIF_FOURNISSEUR_A | B11: FR | C11: EUR | D11: 0.94 | E11: FICTIF – exemple | F11: 46299 | G11: 0 | H11: FR | I11: DAP | J11: 40 | K11: 0 | L11: 25 | M11: 500 | N11: 5 | O11: Prépaiement | P11: CSV | Q11: N | R11: FICTIF | S11: O | T11: =IF(A11="","",IF(AND(B11<>"",C11<>"",D11<>"",E11<>"",F11<>"",G11<>"",H11<>"",J11<>"",K11<>"",L11<>""),1,0)) -> 1
A12: FICTIF_FOURNISSEUR_B | B12: CH | C12: CHF | D12: 1 | E12: CHF (aucune conversion) | F12: 46299 | G12: 0.081 | H12: CH | I12: DAP | J12: 15 | K12: 0 | L12: 0 | M12: 300 | N12: 2 | O12: 30 jours | P12: XLSX | Q12: N | R12: FICTIF | S12: O | T12: =IF(A12="","",IF(AND(B12<>"",C12<>"",D12<>"",E12<>"",F12<>"",G12<>"",H12<>"",J12<>"",K12<>"",L12<>""),1,0)) -> 1
T13: =IF(A13="","",IF(AND(B13<>"",C13<>"",D13<>"",E13<>"",F13<>"",G13<>"",H13<>"",J13<>"",K13<>"",L13<>""),1,0))
T14: =IF(A14="","",IF(AND(B14<>"",C14<>"",D14<>"",E14<>"",F14<>"",G14<>"",H14<>"",J14<>"",K14<>"",L14<>""),1,0))
T15: =IF(A15="","",IF(AND(B15<>"",C15<>"",D15<>"",E15<>"",F15<>"",G15<>"",H15<>"",J15<>"",K15<>"",L15<>""),1,0))
T16: =IF(A16="","",IF(AND(B16<>"",C16<>"",D16<>"",E16<>"",F16<>"",G16<>"",H16<>"",J16<>"",K16<>"",L16<>""),1,0))
T17: =IF(A17="","",IF(AND(B17<>"",C17<>"",D17<>"",E17<>"",F17<>"",G17<>"",H17<>"",J17<>"",K17<>"",L17<>""),1,0))
T18: =IF(A18="","",IF(AND(B18<>"",C18<>"",D18<>"",E18<>"",F18<>"",G18<>"",H18<>"",J18<>"",K18<>"",L18<>""),1,0))
T19: =IF(A19="","",IF(AND(B19<>"",C19<>"",D19<>"",E19<>"",F19<>"",G19<>"",H19<>"",J19<>"",K19<>"",L19<>""),1,0))
T20: =IF(A20="","",IF(AND(B20<>"",C20<>"",D20<>"",E20<>"",F20<>"",G20<>"",H20<>"",J20<>"",K20<>"",L20<>""),1,0))
T21: =IF(A21="","",IF(AND(B21<>"",C21<>"",D21<>"",E21<>"",F21<>"",G21<>"",H21<>"",J21<>"",K21<>"",L21<>""),1,0))
T22: =IF(A22="","",IF(AND(B22<>"",C22<>"",D22<>"",E22<>"",F22<>"",G22<>"",H22<>"",J22<>"",K22<>"",L22<>""),1,0))
T23: =IF(A23="","",IF(AND(B23<>"",C23<>"",D23<>"",E23<>"",F23<>"",G23<>"",H23<>"",J23<>"",K23<>"",L23<>""),1,0))
T24: =IF(A24="","",IF(AND(B24<>"",C24<>"",D24<>"",E24<>"",F24<>"",G24<>"",H24<>"",J24<>"",K24<>"",L24<>""),1,0))

Sheet Offres
A1: Offres — une ligne par couple (référence, fournisseur), à partir d'un devis écrit
A2: Aucun prix réel. Lignes 6-7 = exemple FICTIF. Lignes suivantes = panier pilote pré-rempli pour les 3 fournisseurs FR prioritaires (BP §13), à compléter avec leurs devis.
A3: Saisie : colonnes A à S (jaune). Calcul : colonnes T à AT (gris).
A5: ref_id | B5: Désignation (format + extension + langue) | C5: Fournisseur | D5: SKU fournisseur | E5: EAN / GTIN | F5: Langue confirmée | G5: Extension | H5: Format | I5: Unités par conditionnement | J5: Prix du conditionnement (devise, avant remise) | K5: Base de prix (HT/TTC) | L5: Remise du palier atteint (fraction) | M5: Quantité commandée (conditionnements) | N5: MOQ (conditionnements) | O5: Disponibilité annoncée (unités) | P5: Allocation ferme (O/N) | Q5: Date de dispo / sortie | R5: Prix marché observé TTC (CHF, médiane) | S5: Fictif (O/N) | T5: Devise | U5: Taux → CHF | V5: TVA fournisseur (taux) | W5: Pays TVA | X5: Pays d'expédition | Y5: Complet (1/0) | Z5: Prix cond. après remise (devise) | AA5: Prix HT cond. (devise) | AB5: TVA fournisseur cond. (devise) | AC5: Valeur ligne HT (CHF) | AD5: Part de la commande fournisseur | AE5: Port + frais ventilés / unité (CHF) | AF5: Dédouanement ventilé / unité (CHF) | AG5: Achat HT / unité (CHF) | AH5: TVA fournisseur / unité (CHF) | AI5: TVA fournisseur récupérable (1/0) | AJ5: TVA import estimée / unité (CHF) | AK5: COÛT RENDU C / unité (CHF) | AL5: Prix plancher TTC (CHF) | AM5: Écart plancher / marché | AN5: Contribution au prix marché (CHF) | AO5: Contribution au prix marché (% CA net) | AP5: Statut | AQ5: Alertes | AR5: Rang (1 = moins cher) | AS5: Clé de classement | AT5: Total ligne rendu (CHF)
A6: FICTIF_R00 | B6: FICTIF – ETB d'exemple (aucun produit réel) | C6: FICTIF_FOURNISSEUR_A | D6: FICTIF-A-001 | E6: 2000000001012 | F6: FR | G6: FICTIF | H6: etb | I6: 1 | J6: 40 | K6: HT | L6: 0.05 | M6: 10 | N6: 6 | O6: 50 | P6: N | Q6: 46328 | R6: 69.9 | S6: O | T6: =IF($C6="","",IFERROR(INDEX(Fournisseurs!$C$5:$C$24,MATCH($C6,Fournisseurs!$A$5:$A$24,0)),"")) -> EUR | U6: =IF($C6="","",IFERROR(INDEX(Fournisseurs!$D$5:$D$24,MATCH($C6,Fournisseurs!$A$5:$A$24,0)),"")) -> 0.94 | V6: =IF($C6="","",IFERROR(INDEX(Fournisseurs!$G$5:$G$24,MATCH($C6,Fournisseurs!$A$5:$A$24,0)),"")) -> 0 | W6: =IF($C6="","",IFERROR(INDEX(Fournisseurs!$H$5:$H$24,MATCH($C6,Fournisseurs!$A$5:$A$24,0)),"")) -> FR | X6: =IF($C6="","",IFERROR(INDEX(Fournisseurs!$B$5:$B$24,MATCH($C6,Fournisseurs!$A$5:$A$24,0)),"")) -> FR | Y6: =IF($A6="","",IF(AND($A6<>"",$C6<>"",ISNUMBER($I6),ISNUMBER($J6),ISNUMBER($M6)),IF(AND($I6>=1,$J6>0,OR($K6="HT",$K6="TTC"),$M6>=1,IFERROR(INDEX(Fournisseurs!$T$5:$T$24,MATCH($C6,Fournisseurs!$A$5:$A$24,0)),0)=1),1,0),0)) -> 1 | Z6: =IF($Y6=1,$J6*(1-N($L6)),"") -> 38 | AA6: =IF($Y6=1,IF($K6="TTC",$Z6/(1+$V6),$Z6),"") -> 38 | AB6: =IF($Y6=1,IF($K6="TTC",$Z6-$AA6,$AA6*$V6),"") -> 0 | AC6: =IF($Y6=1,$AA6*$U6*$M6,"") -> 357.2 | AD6: =IF($Y6=1,$AC6/SUMIFS($AC$6:$AC$205,$C$6:$C$205,$C6,$Y$6:$Y$205,1),"") -> 1 | AE6: =IF($Y6=1,(INDEX(Fournisseurs!$J$5:$J$24,MATCH($C6,Fournisseurs!$A$5:$A$24,0))+INDEX(Fournisseurs!$K$5:$K$24,MATCH($C6,Fournisseurs!$A$5:$A$24,0)))*$U6*$AD6/($I6*$M6),"") -> 3.76 | AF6: =IF($Y6=1,INDEX(Fournisseurs!$L$5:$L$24,MATCH($C6,Fournisseurs!$A$5:$A$24,0))*$AD6/($I6*$M6),"") -> 2.5 | AG6: =IF($Y6=1,$AA6*$U6/$I6,"") -> 35.72 | AH6: =IF($Y6=1,$AB6*$U6/$I6,"") -> 0 | AI6: =IF($Y6=1,IF(AND(Paramètres!$B$4="EFFECTIVE",$W6="CH",$AB6>0),1,0),"") -> 0 | AJ6: =IF($Y6=1,IF($X6<>"CH",($AG6+$AE6+$AF6)*Paramètres!$B$14,0),"") -> 3.40038 | AK6: =IF($Y6=1,$AG6+IF($AI6=1,0,$AH6)+$AE6+$AF6+IF(Paramètres!$B$4="NOT_REGISTERED",$AJ6,0),"") -> 41.98 | AL6: =IF($Y6=1,($AK6+Paramètres!$B$7+Paramètres!$B$8+Paramètres!$B$9+Paramètres!$B$10)/((1-Paramètres!$B$11)/(1+Paramètres!$B$5)-Paramètres!$B$6),"") -> 71.714713 | AM6: =IF(AND($Y6=1,ISNUMBER($R6)),IF($R6>0,$AL6/$R6-1,""),"") -> 0.025961554 | AN6: =IF(AND($Y6=1,ISNUMBER($R6)),IF($R6>0,$R6/(1+Paramètres!$B$5)-$AK6-($R6*Paramètres!$B$6+Paramètres!$B$7)-Paramètres!$B$8-Paramètres!$B$9-Paramètres!$B$10,""),"") -> 11.63485 | AO6: =IF(ISNUMBER($AN6),$AN6/($R6/(1+Paramètres!$B$5)),"") -> 0.17993237 | AP6: =IF($A6="","",IF($Y6<>1,"INCOMPLET",IF(NOT(ISNUMBER($AM6)),"SANS RÉF. MARCHÉ",IF($AM6<=Paramètres!$B$12,"OK",IF(AND($AO6>=Paramètres!$B$15,$AN6>=Paramètres!$B$16),"À REVOIR","NON RENTABLE"))))) -> OK | AQ6: =TRIM(IF(AND($Y6=1,ISNUMBER($N6)),IF($M6<$N6,"MOQ ",""),"")&IF(AND($Y6=1,ISNUMBER($O6)),IF($O6<$I6*$M6,"DISPO ",""),"")&IF($S6="O","FICTIF ","")&IF($Y6=1,IF(AND($K6="TTC",$W6<>"CH"),"TVA-ÉTRANGÈRE ",""),"")) -> FICTIF | AR6: =IF($Y6=1,COUNTIFS($A$6:$A$205,$A6,$AK$6:$AK$205,"<"&$AK6,$Y$6:$Y$205,1)+1,"") -> 1 | AS6: =IF(ISNUMBER($AR6),$A6&"|"&$AR6,"") -> FICTIF_R00|1 | AT6: =IF($Y6=1,$AK6*$I6*$M6,"") -> 419.8
A7: FICTIF_R00 | B7: FICTIF – ETB d'exemple (aucun produit réel) | C7: FICTIF_FOURNISSEUR_B | D7: FICTIF-B-001 | E7: 2000000001012 | F7: FR | G7: FICTIF | H7: etb | I7: 1 | J7: 49.9 | K7: TTC | M7: 10 | N7: 1 | O7: 20 | P7: N | Q7: 46315 | R7: 69.9 | S7: O | T7: =IF($C7="","",IFERROR(INDEX(Fournisseurs!$C$5:$C$24,MATCH($C7,Fournisseurs!$A$5:$A$24,0)),"")) -> CHF | U7: =IF($C7="","",IFERROR(INDEX(Fournisseurs!$D$5:$D$24,MATCH($C7,Fournisseurs!$A$5:$A$24,0)),"")) -> 1 | V7: =IF($C7="","",IFERROR(INDEX(Fournisseurs!$G$5:$G$24,MATCH($C7,Fournisseurs!$A$5:$A$24,0)),"")) -> 0.081 | W7: =IF($C7="","",IFERROR(INDEX(Fournisseurs!$H$5:$H$24,MATCH($C7,Fournisseurs!$A$5:$A$24,0)),"")) -> CH | X7: =IF($C7="","",IFERROR(INDEX(Fournisseurs!$B$5:$B$24,MATCH($C7,Fournisseurs!$A$5:$A$24,0)),"")) -> CH | Y7: =IF($A7="","",IF(AND($A7<>"",$C7<>"",ISNUMBER($I7),ISNUMBER($J7),ISNUMBER($M7)),IF(AND($I7>=1,$J7>0,OR($K7="HT",$K7="TTC"),$M7>=1,IFERROR(INDEX(Fournisseurs!$T$5:$T$24,MATCH($C7,Fournisseurs!$A$5:$A$24,0)),0)=1),1,0),0)) -> 1 | Z7: =IF($Y7=1,$J7*(1-N($L7)),"") -> 49.9 | AA7: =IF($Y7=1,IF($K7="TTC",$Z7/(1+$V7),$Z7),"") -> 46.160962 | AB7: =IF($Y7=1,IF($K7="TTC",$Z7-$AA7,$AA7*$V7),"") -> 3.7390379 | AC7: =IF($Y7=1,$AA7*$U7*$M7,"") -> 461.60962 | AD7: =IF($Y7=1,$AC7/SUMIFS($AC$6:$AC$205,$C$6:$C$205,$C7,$Y$6:$Y$205,1),"") -> 1 | AE7: =IF($Y7=1,(INDEX(Fournisseurs!$J$5:$J$24,MATCH($C7,Fournisseurs!$A$5:$A$24,0))+INDEX(Fournisseurs!$K$5:$K$24,MATCH($C7,Fournisseurs!$A$5:$A$24,0)))*$U7*$AD7/($I7*$M7),"") -> 1.5 | AF7: =IF($Y7=1,INDEX(Fournisseurs!$L$5:$L$24,MATCH($C7,Fournisseurs!$A$5:$A$24,0))*$AD7/($I7*$M7),"") -> 0 | AG7: =IF($Y7=1,$AA7*$U7/$I7,"") -> 46.160962 | AH7: =IF($Y7=1,$AB7*$U7/$I7,"") -> 3.7390379 | AI7: =IF($Y7=1,IF(AND(Paramètres!$B$4="EFFECTIVE",$W7="CH",$AB7>0),1,0),"") -> 1 | AJ7: =IF($Y7=1,IF($X7<>"CH",($AG7+$AE7+$AF7)*Paramètres!$B$14,0),"") -> 0 | AK7: =IF($Y7=1,$AG7+IF($AI7=1,0,$AH7)+$AE7+$AF7+IF(Paramètres!$B$4="NOT_REGISTERED",$AJ7,0),"") -> 47.660962 | AL7: =IF($Y7=1,($AK7+Paramètres!$B$7+Paramètres!$B$8+Paramètres!$B$9+Paramètres!$B$10)/((1-Paramètres!$B$11)/(1+Paramètres!$B$5)-Paramètres!$B$6),"") -> 79.659497 | AM7: =IF(AND($Y7=1,ISNUMBER($R7)),IF($R7>0,$AL7/$R7-1,""),"") -> 0.13962085 | AN7: =IF(AND($Y7=1,ISNUMBER($R7)),IF($R7>0,$R7/(1+Paramètres!$B$5)-$AK7-($R7*Paramètres!$B$6+Paramètres!$B$7)-Paramètres!$B$8-Paramètres!$B$9-Paramètres!$B$10,""),"") -> 5.9538876 | AO7: =IF(ISNUMBER($AN7),$AN7/($R7/(1+Paramètres!$B$5)),"") -> 0.092076574 | AP7: =IF($A7="","",IF($Y7<>1,"INCOMPLET",IF(NOT(ISNUMBER($AM7)),"SANS RÉF. MARCHÉ",IF($AM7<=Paramètres!$B$12,"OK",IF(AND($AO7>=Paramètres!$B$15,$AN7>=Paramètres!$B$16),"À REVOIR","NON RENTABLE"))))) -> NON RENTABLE | AQ7: =TRIM(IF(AND($Y7=1,ISNUMBER($N7)),IF($M7<$N7,"MOQ ",""),"")&IF(AND($Y7=1,ISNUMBER($O7)),IF($O7<$I7*$M7,"DISPO ",""),"")&IF($S7="O","FICTIF ","")&IF($Y7=1,IF(AND($K7="TTC",$W7<>"CH"),"TVA-ÉTRANGÈRE ",""),"")) -> FICTIF | AR7: =IF($Y7=1,COUNTIFS($A$6:$A$205,$A7,$AK$6:$AK$205,"<"&$AK7,$Y$6:$Y$205,1)+1,"") -> 2 | AS7: =IF(ISNUMBER($AR7),$A7&"|"&$AR7,"") -> FICTIF_R00|2 | AT7: =IF($Y7=1,$AK7*$I7*$M7,"") -> 476.60962
A8: REF-06 | B8: Display 36 boosters Méga-Évolution – Nuit Noire (ME05) – FR | C8: Asmodee France | G8: Méga-Évolution – Nuit Noire | H8: display | S8: N | T8: =IF($C8="","",IFERROR(INDEX(Fournisseurs!$C$5:$C$24,MATCH($C8,Fournisseurs!$A$5:$A$24,0)),"")) -> 0 | U8: =IF($C8="","",IFERROR(INDEX(Fournisseurs!$D$5:$D$24,MATCH($C8,Fournisseurs!$A$5:$A$24,0)),"")) -> 0 | V8: =IF($C8="","",IFERROR(INDEX(Fournisseurs!$G$5:$G$24,MATCH($C8,Fournisseurs!$A$5:$A$24,0)),"")) -> 0 | W8: =IF($C8="","",IFERROR(INDEX(Fournisseurs!$H$5:$H$24,MATCH($C8,Fournisseurs!$A$5:$A$24,0)),"")) -> 0 | X8: =IF($C8="","",IFERROR(INDEX(Fournisseurs!$B$5:$B$24,MATCH($C8,Fournisseurs!$A$5:$A$24,0)),"")) -> 0 | Y8: =IF($A8="","",IF(AND($A8<>"",$C8<>"",ISNUMBER($I8),ISNUMBER($J8),ISNUMBER($M8)),IF(AND($I8>=1,$J8>0,OR($K8="HT",$K8="TTC"),$M8>=1,IFERROR(INDEX(Fournisseurs!$T$5:$T$24,MATCH($C8,Fournisseurs!$A$5:$A$24,0)),0)=1),1,0),0)) -> 0 | Z8: =IF($Y8=1,$J8*(1-N($L8)),"") | AA8: =IF($Y8=1,IF($K8="TTC",$Z8/(1+$V8),$Z8),"") | AB8: =IF($Y8=1,IF($K8="TTC",$Z8-$AA8,$AA8*$V8),"") | AC8: =IF($Y8=1,$AA8*$U8*$M8,"") | AD8: =IF($Y8=1,$AC8/SUMIFS($AC$6:$AC$205,$C$6:$C$205,$C8,$Y$6:$Y$205,1),"") | AE8: =IF($Y8=1,(INDEX(Fournisseurs!$J$5:$J$24,MATCH($C8,Fournisseurs!$A$5:$A$24,0))+INDEX(Fournisseurs!$K$5:$K$24,MATCH($C8,Fournisseurs!$A$5:$A$24,0)))*$U8*$AD8/($I8*$M8),"") | AF8: =IF($Y8=1,INDEX(Fournisseurs!$L$5:$L$24,MATCH($C8,Fournisseurs!$A$5:$A$24,0))*$AD8/($I8*$M8),"") | AG8: =IF($Y8=1,$AA8*$U8/$I8,"") | AH8: =IF($Y8=1,$AB8*$U8/$I8,"") | AI8: =IF($Y8=1,IF(AND(Paramètres!$B$4="EFFECTIVE",$W8="CH",$AB8>0),1,0),"") | AJ8: =IF($Y8=1,IF($X8<>"CH",($AG8+$AE8+$AF8)*Paramètres!$B$14,0),"") | AK8: =IF($Y8=1,$AG8+IF($AI8=1,0,$AH8)+$AE8+$AF8+IF(Paramètres!$B$4="NOT_REGISTERED",$AJ8,0),"") | AL8: =IF($Y8=1,($AK8+Paramètres!$B$7+Paramètres!$B$8+Paramètres!$B$9+Paramètres!$B$10)/((1-Paramètres!$B$11)/(1+Paramètres!$B$5)-Paramètres!$B$6),"") | AM8: =IF(AND($Y8=1,ISNUMBER($R8)),IF($R8>0,$AL8/$R8-1,""),"") | AN8: =IF(AND($Y8=1,ISNUMBER($R8)),IF($R8>0,$R8/(1+Paramètres!$B$5)-$AK8-($R8*Paramètres!$B$6+Paramètres!$B$7)-Paramètres!$B$8-Paramètres!$B$9-Paramètres!$B$10,""),"") | AO8: =IF(ISNUMBER($AN8),$AN8/($R8/(1+Paramètres!$B$5)),"") | AP8: =IF($A8="","",IF($Y8<>1,"INCOMPLET",IF(NOT(ISNUMBER($AM8)),"SANS RÉF. MARCHÉ",IF($AM8<=Paramètres!$B$12,"OK",IF(AND($AO8>=Paramètres!$B$15,$AN8>=Paramètres!$B$16),"À REVOIR","NON RENTABLE"))))) -> INCOMPLET | AQ8: =TRIM(IF(AND($Y8=1,ISNUMBER($N8)),IF($M8<$N8,"MOQ ",""),"")&IF(AND($Y8=1,ISNUMBER($O8)),IF($O8<$I8*$M8,"DISPO ",""),"")&IF($S8="O","FICTIF ","")&IF($Y8=1,IF(AND($K8="TTC",$W8<>"CH"),"TVA-ÉTRANGÈRE ",""),"")) | AR8: =IF($Y8=1,COUNTIFS($A$6:$A$205,$A8,$AK$6:$AK$205,"<"&$AK8,$Y$6:$Y$205,1)+1,"") | AS8: =IF(ISNUMBER($AR8),$A8&"|"&$AR8,"") | AT8: =IF($Y8=1,$AK8*$I8*$M8,"")
A9: REF-09 | B9: Display 36 boosters Méga-Évolution – Chaos Ascendant – FR | C9: Asmodee France | G9: Méga-Évolution – Chaos Ascendant | H9: display | S9: N | T9: =IF($C9="","",IFERROR(INDEX(Fournisseurs!$C$5:$C$24,MATCH($C9,Fournisseurs!$A$5:$A$24,0)),"")) -> 0 | U9: =IF($C9="","",IFERROR(INDEX(Fournisseurs!$D$5:$D$24,MATCH($C9,Fournisseurs!$A$5:$A$24,0)),"")) -> 0 | V9: =IF($C9="","",IFERROR(INDEX(Fournisseurs!$G$5:$G$24,MATCH($C9,Fournisseurs!$A$5:$A$24,0)),"")) -> 0 | W9: =IF($C9="","",IFERROR(INDEX(Fournisseurs!$H$5:$H$24,MATCH($C9,Fournisseurs!$A$5:$A$24,0)),"")) -> 0 | X9: =IF($C9="","",IFERROR(INDEX(Fournisseurs!$B$5:$B$24,MATCH($C9,Fournisseurs!$A$5:$A$24,0)),"")) -> 0 | Y9: =IF($A9="","",IF(AND($A9<>"",$C9<>"",ISNUMBER($I9),ISNUMBER($J9),ISNUMBER($M9)),IF(AND($I9>=1,$J9>0,OR($K9="HT",$K9="TTC"),$M9>=1,IFERROR(INDEX(Fournisseurs!$T$5:$T$24,MATCH($C9,Fournisseurs!$A$5:$A$24,0)),0)=1),1,0),0)) -> 0 | Z9: =IF($Y9=1,$J9*(1-N($L9)),"") | AA9: =IF($Y9=1,IF($K9="TTC",$Z9/(1+$V9),$Z9),"") | AB9: =IF($Y9=1,IF($K9="TTC",$Z9-$AA9,$AA9*$V9),"") | AC9: =IF($Y9=1,$AA9*$U9*$M9,"") | AD9: =IF($Y9=1,$AC9/SUMIFS($AC$6:$AC$205,$C$6:$C$205,$C9,$Y$6:$Y$205,1),"") | AE9: =IF($Y9=1,(INDEX(Fournisseurs!$J$5:$J$24,MATCH($C9,Fournisseurs!$A$5:$A$24,0))+INDEX(Fournisseurs!$K$5:$K$24,MATCH($C9,Fournisseurs!$A$5:$A$24,0)))*$U9*$AD9/($I9*$M9),"") | AF9: =IF($Y9=1,INDEX(Fournisseurs!$L$5:$L$24,MATCH($C9,Fournisseurs!$A$5:$A$24,0))*$AD9/($I9*$M9),"") | AG9: =IF($Y9=1,$AA9*$U9/$I9,"") | AH9: =IF($Y9=1,$AB9*$U9/$I9,"") | AI9: =IF($Y9=1,IF(AND(Paramètres!$B$4="EFFECTIVE",$W9="CH",$AB9>0),1,0),"") | AJ9: =IF($Y9=1,IF($X9<>"CH",($AG9+$AE9+$AF9)*Paramètres!$B$14,0),"") | AK9: =IF($Y9=1,$AG9+IF($AI9=1,0,$AH9)+$AE9+$AF9+IF(Paramètres!$B$4="NOT_REGISTERED",$AJ9,0),"") | AL9: =IF($Y9=1,($AK9+Paramètres!$B$7+Paramètres!$B$8+Paramètres!$B$9+Paramètres!$B$10)/((1-Paramètres!$B$11)/(1+Paramètres!$B$5)-Paramètres!$B$6),"") | AM9: =IF(AND($Y9=1,ISNUMBER($R9)),IF($R9>0,$AL9/$R9-1,""),"") | AN9: =IF(AND($Y9=1,ISNUMBER($R9)),IF($R9>0,$R9/(1+Paramètres!$B$5)-$AK9-($R9*Paramètres!$B$6+Paramètres!$B$7)-Paramètres!$B$8-Paramètres!$B$9-Paramètres!$B$10,""),"") | AO9: =IF(ISNUMBER($AN9),$AN9/($R9/(1+Paramètres!$B$5)),"") | AP9: =IF($A9="","",IF($Y9<>1,"INCOMPLET",IF(NOT(ISNUMBER($AM9)),"SANS RÉF. MARCHÉ",IF($AM9<=Paramètres!$B$12,"OK",IF(AND($AO9>=Paramètres!$B$15,$AN9>=Paramètres!$B$16),"À REVOIR","NON RENTABLE"))))) -> INCOMPLET | AQ9: =TRIM(IF(AND($Y9=1,ISNUMBER($N9)),IF($M9<$N9,"MOQ ",""),"")&IF(AND($Y9=1,ISNUMBER($O9)),IF($O9<$I9*$M9,"DISPO ",""),"")&IF($S9="O","FICTIF ","")&IF($Y9=1,IF(AND($K9="TTC",$W9<>"CH"),"TVA-ÉTRANGÈRE ",""),"")) | AR9: =IF($Y9=1,COUNTIFS($A$6:$A$205,$A9,$AK$6:$AK$205,"<"&$AK9,$Y$6:$Y$205,1)+1,"") | AS9: =IF(ISNUMBER($AR9),$A9&"|"&$AR9,"") | AT9: =IF($Y9=1,$AK9*$I9*$M9,"")
A10: REF-01 | B10: Coffret Dresseur d'Élite (ETB) 30ᵉ Anniversaire – FR | C10: Asmodee France | G10: 30ᵉ Anniversaire | H10: etb | S10: N | T10: =IF($C10="","",IFERROR(INDEX(Fournisseurs!$C$5:$C$24,MATCH($C10,Fournisseurs!$A$5:$A$24,0)),"")) -> 0 | U10: =IF($C10="","",IFERROR(INDEX(Fournisseurs!$D$5:$D$24,MATCH($C10,Fournisseurs!$A$5:$A$24,0)),"")) -> 0 | V10: =IF($C10="","",IFERROR(INDEX(Fournisseurs!$G$5:$G$24,MATCH($C10,Fournisseurs!$A$5:$A$24,0)),"")) -> 0 | W10: =IF($C10="","",IFERROR(INDEX(Fournisseurs!$H$5:$H$24,MATCH($C10,Fournisseurs!$A$5:$A$24,0)),"")) -> 0 | X10: =IF($C10="","",IFERROR(INDEX(Fournisseurs!$B$5:$B$24,MATCH($C10,Fournisseurs!$A$5:$A$24,0)),"")) -> 0 | Y10: =IF($A10="","",IF(AND($A10<>"",$C10<>"",ISNUMBER($I10),ISNUMBER($J10),ISNUMBER($M10)),IF(AND($I10>=1,$J10>0,OR($K10="HT",$K10="TTC"),$M10>=1,IFERROR(INDEX(Fournisseurs!$T$5:$T$24,MATCH($C10,Fournisseurs!$A$5:$A$24,0)),0)=1),1,0),0)) -> 0 | Z10: =IF($Y10=1,$J10*(1-N($L10)),"") | AA10: =IF($Y10=1,IF($K10="TTC",$Z10/(1+$V10),$Z10),"") | AB10: =IF($Y10=1,IF($K10="TTC",$Z10-$AA10,$AA10*$V10),"") | AC10: =IF($Y10=1,$AA10*$U10*$M10,"") | AD10: =IF($Y10=1,$AC10/SUMIFS($AC$6:$AC$205,$C$6:$C$205,$C10,$Y$6:$Y$205,1),"") | AE10: =IF($Y10=1,(INDEX(Fournisseurs!$J$5:$J$24,MATCH($C10,Fournisseurs!$A$5:$A$24,0))+INDEX(Fournisseurs!$K$5:$K$24,MATCH($C10,Fournisseurs!$A$5:$A$24,0)))*$U10*$AD10/($I10*$M10),"") | AF10: =IF($Y10=1,INDEX(Fournisseurs!$L$5:$L$24,MATCH($C10,Fournisseurs!$A$5:$A$24,0))*$AD10/($I10*$M10),"") | AG10: =IF($Y10=1,$AA10*$U10/$I10,"") | AH10: =IF($Y10=1,$AB10*$U10/$I10,"") | AI10: =IF($Y10=1,IF(AND(Paramètres!$B$4="EFFECTIVE",$W10="CH",$AB10>0),1,0),"") | AJ10: =IF($Y10=1,IF($X10<>"CH",($AG10+$AE10+$AF10)*Paramètres!$B$14,0),"") | AK10: =IF($Y10=1,$AG10+IF($AI10=1,0,$AH10)+$AE10+$AF10+IF(Paramètres!$B$4="NOT_REGISTERED",$AJ10,0),"") | AL10: =IF($Y10=1,($AK10+Paramètres!$B$7+Paramètres!$B$8+Paramètres!$B$9+Paramètres!$B$10)/((1-Paramètres!$B$11)/(1+Paramètres!$B$5)-Paramètres!$B$6),"") | AM10: =IF(AND($Y10=1,ISNUMBER($R10)),IF($R10>0,$AL10/$R10-1,""),"") | AN10: =IF(AND($Y10=1,ISNUMBER($R10)),IF($R10>0,$R10/(1+Paramètres!$B$5)-$AK10-($R10*Paramètres!$B$6+Paramètres!$B$7)-Paramètres!$B$8-Paramètres!$B$9-Paramètres!$B$10,""),"") | AO10: =IF(ISNUMBER($AN10),$AN10/($R10/(1+Paramètres!$B$5)),"") | AP10: =IF($A10="","",IF($Y10<>1,"INCOMPLET",IF(NOT(ISNUMBER($AM10)),"SANS RÉF. MARCHÉ",IF($AM10<=Paramètres!$B$12,"OK",IF(AND($AO10>=Paramètres!$B$15,$AN10>=Paramètres!$B$16),"À REVOIR","NON RENTABLE"))))) -> INCOMPLET | AQ10: =TRIM(IF(AND($Y10=1,ISNUMBER($N10)),IF($M10<$N10,"MOQ ",""),"")&IF(AND($Y10=1,ISNUMBER($O10)),IF($O10<$I10*$M10,"DISPO ",""),"")&IF($S10="O","FICTIF ","")&IF($Y10=1,IF(AND($K10="TTC",$W10<>"CH"),"TVA-ÉTRANGÈRE ",""),"")) | AR10: =IF($Y10=1,COUNTIFS($A$6:$A$205,$A10,$AK$6:$AK$205,"<"&$AK10,$Y$6:$Y$205,1)+1,"") | AS10: =IF(ISNUMBER($AR10),$A10&"|"&$AR10,"") | AT10: =IF($Y10=1,$AK10*$I10*$M10,"")
A11: REF-07 | B11: Coffret Dresseur d'Élite (ETB) Méga-Évolution – Nuit Noire – FR | C11: Asmodee France | G11: Méga-Évolution – Nuit Noire | H11: etb | S11: N | T11: =IF($C11="","",IFERROR(INDEX(Fournisseurs!$C$5:$C$24,MATCH($C11,Fournisseurs!$A$5:$A$24,0)),"")) -> 0 | U11: =IF($C11="","",IFERROR(INDEX(Fournisseurs!$D$5:$D$24,MATCH($C11,Fournisseurs!$A$5:$A$24,0)),"")) -> 0 | V11: =IF($C11="","",IFERROR(INDEX(Fournisseurs!$G$5:$G$24,MATCH($C11,Fournisseurs!$A$5:$A$24,0)),"")) -> 0 | W11: =IF($C11="","",IFERROR(INDEX(Fournisseurs!$H$5:$H$24,MATCH($C11,Fournisseurs!$A$5:$A$24,0)),"")) -> 0 | X11: =IF($C11="","",IFERROR(INDEX(Fournisseurs!$B$5:$B$24,MATCH($C11,Fournisseurs!$A$5:$A$24,0)),"")) -> 0 | Y11: =IF($A11="","",IF(AND($A11<>"",$C11<>"",ISNUMBER($I11),ISNUMBER($J11),ISNUMBER($M11)),IF(AND($I11>=1,$J11>0,OR($K11="HT",$K11="TTC"),$M11>=1,IFERROR(INDEX(Fournisseurs!$T$5:$T$24,MATCH($C11,Fournisseurs!$A$5:$A$24,0)),0)=1),1,0),0)) -> 0 | Z11: =IF($Y11=1,$J11*(1-N($L11)),"") | AA11: =IF($Y11=1,IF($K11="TTC",$Z11/(1+$V11),$Z11),"") | AB11: =IF($Y11=1,IF($K11="TTC",$Z11-$AA11,$AA11*$V11),"") | AC11: =IF($Y11=1,$AA11*$U11*$M11,"") | AD11: =IF($Y11=1,$AC11/SUMIFS($AC$6:$AC$205,$C$6:$C$205,$C11,$Y$6:$Y$205,1),"") | AE11: =IF($Y11=1,(INDEX(Fournisseurs!$J$5:$J$24,MATCH($C11,Fournisseurs!$A$5:$A$24,0))+INDEX(Fournisseurs!$K$5:$K$24,MATCH($C11,Fournisseurs!$A$5:$A$24,0)))*$U11*$AD11/($I11*$M11),"") | AF11: =IF($Y11=1,INDEX(Fournisseurs!$L$5:$L$24,MATCH($C11,Fournisseurs!$A$5:$A$24,0))*$AD11/($I11*$M11),"") | AG11: =IF($Y11=1,$AA11*$U11/$I11,"") | AH11: =IF($Y11=1,$AB11*$U11/$I11,"") | AI11: =IF($Y11=1,IF(AND(Paramètres!$B$4="EFFECTIVE",$W11="CH",$AB11>0),1,0),"") | AJ11: =IF($Y11=1,IF($X11<>"CH",($AG11+$AE11+$AF11)*Paramètres!$B$14,0),"") | AK11: =IF($Y11=1,$AG11+IF($AI11=1,0,$AH11)+$AE11+$AF11+IF(Paramètres!$B$4="NOT_REGISTERED",$AJ11,0),"") | AL11: =IF($Y11=1,($AK11+Paramètres!$B$7+Paramètres!$B$8+Paramètres!$B$9+Paramètres!$B$10)/((1-Paramètres!$B$11)/(1+Paramètres!$B$5)-Paramètres!$B$6),"") | AM11: =IF(AND($Y11=1,ISNUMBER($R11)),IF($R11>0,$AL11/$R11-1,""),"") | AN11: =IF(AND($Y11=1,ISNUMBER($R11)),IF($R11>0,$R11/(1+Paramètres!$B$5)-$AK11-($R11*Paramètres!$B$6+Paramètres!$B$7)-Paramètres!$B$8-Paramètres!$B$9-Paramètres!$B$10,""),"") | AO11: =IF(ISNUMBER($AN11),$AN11/($R11/(1+Paramètres!$B$5)),"") | AP11: =IF($A11="","",IF($Y11<>1,"INCOMPLET",IF(NOT(ISNUMBER($AM11)),"SANS RÉF. MARCHÉ",IF($AM11<=Paramètres!$B$12,"OK",IF(AND($AO11>=Paramètres!$B$15,$AN11>=Paramètres!$B$16),"À REVOIR","NON RENTABLE"))))) -> INCOMPLET | AQ11: =TRIM(IF(AND($Y11=1,ISNUMBER($N11)),IF($M11<$N11,"MOQ ",""),"")&IF(AND($Y11=1,ISNUMBER($O11)),IF($O11<$I11*$M11,"DISPO ",""),"")&IF($S11="O","FICTIF ","")&IF($Y11=1,IF(AND($K11="TTC",$W11<>"CH"),"TVA-ÉTRANGÈRE ",""),"")) | AR11: =IF($Y11=1,COUNTIFS($A$6:$A$205,$A11,$AK$6:$AK$205,"<"&$AK11,$Y$6:$Y$205,1)+1,"") | AS11: =IF(ISNUMBER($AR11),$A11&"|"&$AR11,"") | AT11: =IF($Y11=1,$AK11*$I11*$M11,"")
A12: REF-11 | B12: Coffret Dresseur d'Élite (ETB) Méga-Évolution – Équilibre Parfait – FR | C12: Asmodee France | G12: Méga-Évolution – Équilibre Parfait | H12: etb | S12: N | T12: =IF($C12="","",IFERROR(INDEX(Fournisseurs!$C$5:$C$24,MATCH($C12,Fournisseurs!$A$5:$A$24,0)),"")) -> 0 | U12: =IF($C12="","",IFERROR(INDEX(Fournisseurs!$D$5:$D$24,MATCH($C12,Fournisseurs!$A$5:$A$24,0)),"")) -> 0 | V12: =IF($C12="","",IFERROR(INDEX(Fournisseurs!$G$5:$G$24,MATCH($C12,Fournisseurs!$A$5:$A$24,0)),"")) -> 0 | W12: =IF($C12="","",IFERROR(INDEX(Fournisseurs!$H$5:$H$24,MATCH($C12,Fournisseurs!$A$5:$A$24,0)),"")) -> 0 | X12: =IF($C12="","",IFERROR(INDEX(Fournisseurs!$B$5:$B$24,MATCH($C12,Fournisseurs!$A$5:$A$24,0)),"")) -> 0 | Y12: =IF($A12="","",IF(AND($A12<>"",$C12<>"",ISNUMBER($I12),ISNUMBER($J12),ISNUMBER($M12)),IF(AND($I12>=1,$J12>0,OR($K12="HT",$K12="TTC"),$M12>=1,IFERROR(INDEX(Fournisseurs!$T$5:$T$24,MATCH($C12,Fournisseurs!$A$5:$A$24,0)),0)=1),1,0),0)) -> 0 | Z12: =IF($Y12=1,$J12*(1-N($L12)),"") | AA12: =IF($Y12=1,IF($K12="TTC",$Z12/(1+$V12),$Z12),"") | AB12: =IF($Y12=1,IF($K12="TTC",$Z12-$AA12,$AA12*$V12),"") | AC12: =IF($Y12=1,$AA12*$U12*$M12,"") | AD12: =IF($Y12=1,$AC12/SUMIFS($AC$6:$AC$205,$C$6:$C$205,$C12,$Y$6:$Y$205,1),"") | AE12: =IF($Y12=1,(INDEX(Fournisseurs!$J$5:$J$24,MATCH($C12,Fournisseurs!$A$5:$A$24,0))+INDEX(Fournisseurs!$K$5:$K$24,MATCH($C12,Fournisseurs!$A$5:$A$24,0)))*$U12*$AD12/($I12*$M12),"") | AF12: =IF($Y12=1,INDEX(Fournisseurs!$L$5:$L$24,MATCH($C12,Fournisseurs!$A$5:$A$24,0))*$AD12/($I12*$M12),"") | AG12: =IF($Y12=1,$AA12*$U12/$I12,"") | AH12: =IF($Y12=1,$AB12*$U12/$I12,"") | AI12: =IF($Y12=1,IF(AND(Paramètres!$B$4="EFFECTIVE",$W12="CH",$AB12>0),1,0),"") | AJ12: =IF($Y12=1,IF($X12<>"CH",($AG12+$AE12+$AF12)*Paramètres!$B$14,0),"") | AK12: =IF($Y12=1,$AG12+IF($AI12=1,0,$AH12)+$AE12+$AF12+IF(Paramètres!$B$4="NOT_REGISTERED",$AJ12,0),"") | AL12: =IF($Y12=1,($AK12+Paramètres!$B$7+Paramètres!$B$8+Paramètres!$B$9+Paramètres!$B$10)/((1-Paramètres!$B$11)/(1+Paramètres!$B$5)-Paramètres!$B$6),"") | AM12: =IF(AND($Y12=1,ISNUMBER($R12)),IF($R12>0,$AL12/$R12-1,""),"") | AN12: =IF(AND($Y12=1,ISNUMBER($R12)),IF($R12>0,$R12/(1+Paramètres!$B$5)-$AK12-($R12*Paramètres!$B$6+Paramètres!$B$7)-Paramètres!$B$8-Paramètres!$B$9-Paramètres!$B$10,""),"") | AO12: =IF(ISNUMBER($AN12),$AN12/($R12/(1+Paramètres!$B$5)),"") | AP12: =IF($A12="","",IF($Y12<>1,"INCOMPLET",IF(NOT(ISNUMBER($AM12)),"SANS RÉF. MARCHÉ",IF($AM12<=Paramètres!$B$12,"OK",IF(AND($AO12>=Paramètres!$B$15,$AN12>=Paramètres!$B$16),"À REVOIR","NON RENTABLE"))))) -> INCOMPLET | AQ12: =TRIM(IF(AND($Y12=1,ISNUMBER($N12)),IF($M12<$N12,"MOQ ",""),"")&IF(AND($Y12=1,ISNUMBER($O12)),IF($O12<$I12*$M12,"DISPO ",""),"")&IF($S12="O","FICTIF ","")&IF($Y12=1,IF(AND($K12="TTC",$W12<>"CH"),"TVA-ÉTRANGÈRE ",""),"")) | AR12: =IF($Y12=1,COUNTIFS($A$6:$A$205,$A12,$AK$6:$AK$205,"<"&$AK12,$Y$6:$Y$205,1)+1,"") | AS12: =IF(ISNUMBER($AR12),$A12&"|"&$AR12,"") | AT12: =IF($Y12=1,$AK12*$I12*$M12,"")
A13: REF-02 | B13: Bundle 30ᵉ Anniversaire – FR | C13: Asmodee France | G13: 30ᵉ Anniversaire | H13: bundle | S13: N | T13: =IF($C13="","",IFERROR(INDEX(Fournisseurs!$C$5:$C$24,MATCH($C13,Fournisseurs!$A$5:$A$24,0)),"")) -> 0 | U13: =IF($C13="","",IFERROR(INDEX(Fournisseurs!$D$5:$D$24,MATCH($C13,Fournisseurs!$A$5:$A$24,0)),"")) -> 0 | V13: =IF($C13="","",IFERROR(INDEX(Fournisseurs!$G$5:$G$24,MATCH($C13,Fournisseurs!$A$5:$A$24,0)),"")) -> 0 | W13: =IF($C13="","",IFERROR(INDEX(Fournisseurs!$H$5:$H$24,MATCH($C13,Fournisseurs!$A$5:$A$24,0)),"")) -> 0 | X13: =IF($C13="","",IFERROR(INDEX(Fournisseurs!$B$5:$B$24,MATCH($C13,Fournisseurs!$A$5:$A$24,0)),"")) -> 0 | Y13: =IF($A13="","",IF(AND($A13<>"",$C13<>"",ISNUMBER($I13),ISNUMBER($J13),ISNUMBER($M13)),IF(AND($I13>=1,$J13>0,OR($K13="HT",$K13="TTC"),$M13>=1,IFERROR(INDEX(Fournisseurs!$T$5:$T$24,MATCH($C13,Fournisseurs!$A$5:$A$24,0)),0)=1),1,0),0)) -> 0 | Z13: =IF($Y13=1,$J13*(1-N($L13)),"") | AA13: =IF($Y13=1,IF($K13="TTC",$Z13/(1+$V13),$Z13),"") | AB13: =IF($Y13=1,IF($K13="TTC",$Z13-$AA13,$AA13*$V13),"") | AC13: =IF($Y13=1,$AA13*$U13*$M13,"") | AD13: =IF($Y13=1,$AC13/SUMIFS($AC$6:$AC$205,$C$6:$C$205,$C13,$Y$6:$Y$205,1),"") | AE13: =IF($Y13=1,(INDEX(Fournisseurs!$J$5:$J$24,MATCH($C13,Fournisseurs!$A$5:$A$24,0))+INDEX(Fournisseurs!$K$5:$K$24,MATCH($C13,Fournisseurs!$A$5:$A$24,0)))*$U13*$AD13/($I13*$M13),"") | AF13: =IF($Y13=1,INDEX(Fournisseurs!$L$5:$L$24,MATCH($C13,Fournisseurs!$A$5:$A$24,0))*$AD13/($I13*$M13),"") | AG13: =IF($Y13=1,$AA13*$U13/$I13,"") | AH13: =IF($Y13=1,$AB13*$U13/$I13,"") | AI13: =IF($Y13=1,IF(AND(Paramètres!$B$4="EFFECTIVE",$W13="CH",$AB13>0),1,0),"") | AJ13: =IF($Y13=1,IF($X13<>"CH",($AG13+$AE13+$AF13)*Paramètres!$B$14,0),"") | AK13: =IF($Y13=1,$AG13+IF($AI13=1,0,$AH13)+$AE13+$AF13+IF(Paramètres!$B$4="NOT_REGISTERED",$AJ13,0),"") | AL13: =IF($Y13=1,($AK13+Paramètres!$B$7+Paramètres!$B$8+Paramètres!$B$9+Paramètres!$B$10)/((1-Paramètres!$B$11)/(1+Paramètres!$B$5)-Paramètres!$B$6),"") | AM13: =IF(AND($Y13=1,ISNUMBER($R13)),IF($R13>0,$AL13/$R13-1,""),"") | AN13: =IF(AND($Y13=1,ISNUMBER($R13)),IF($R13>0,$R13/(1+Paramètres!$B$5)-$AK13-($R13*Paramètres!$B$6+Paramètres!$B$7)-Paramètres!$B$8-Paramètres!$B$9-Paramètres!$B$10,""),"") | AO13: =IF(ISNUMBER($AN13),$AN13/($R13/(1+Paramètres!$B$5)),"") | AP13: =IF($A13="","",IF($Y13<>1,"INCOMPLET",IF(NOT(ISNUMBER($AM13)),"SANS RÉF. MARCHÉ",IF($AM13<=Paramètres!$B$12,"OK",IF(AND($AO13>=Paramètres!$B$15,$AN13>=Paramètres!$B$16),"À REVOIR","NON RENTABLE"))))) -> INCOMPLET | AQ13: =TRIM(IF(AND($Y13=1,ISNUMBER($N13)),IF($M13<$N13,"MOQ ",""),"")&IF(AND($Y13=1,ISNUMBER($O13)),IF($O13<$I13*$M13,"DISPO ",""),"")&IF($S13="O","FICTIF ","")&IF($Y13=1,IF(AND($K13="TTC",$W13<>"CH"),"TVA-ÉTRANGÈRE ",""),"")) | AR13: =IF($Y13=1,COUNTIFS($A$6:$A$205,$A13,$AK$6:$AK$205,"<"&$AK13,$Y$6:$Y$205,1)+1,"") | AS13: =IF(ISNUMBER($AR13),$A13&"|"&$AR13,"") | AT13: =IF($Y13=1,$AK13*$I13*$M13,"")
A14: REF-08 | B14: Tripack Méga-Évolution – Nuit Noire – FR | C14: Asmodee France | G14: Méga-Évolution – Nuit Noire | H14: tripack | S14: N | T14: =IF($C14="","",IFERROR(INDEX(Fournisseurs!$C$5:$C$24,MATCH($C14,Fournisseurs!$A$5:$A$24,0)),"")) -> 0 | U14: =IF($C14="","",IFERROR(INDEX(Fournisseurs!$D$5:$D$24,MATCH($C14,Fournisseurs!$A$5:$A$24,0)),"")) -> 0 | V14: =IF($C14="","",IFERROR(INDEX(Fournisseurs!$G$5:$G$24,MATCH($C14,Fournisseurs!$A$5:$A$24,0)),"")) -> 0 | W14: =IF($C14="","",IFERROR(INDEX(Fournisseurs!$H$5:$H$24,MATCH($C14,Fournisseurs!$A$5:$A$24,0)),"")) -> 0 | X14: =IF($C14="","",IFERROR(INDEX(Fournisseurs!$B$5:$B$24,MATCH($C14,Fournisseurs!$A$5:$A$24,0)),"")) -> 0 | Y14: =IF($A14="","",IF(AND($A14<>"",$C14<>"",ISNUMBER($I14),ISNUMBER($J14),ISNUMBER($M14)),IF(AND($I14>=1,$J14>0,OR($K14="HT",$K14="TTC"),$M14>=1,IFERROR(INDEX(Fournisseurs!$T$5:$T$24,MATCH($C14,Fournisseurs!$A$5:$A$24,0)),0)=1),1,0),0)) -> 0 | Z14: =IF($Y14=1,$J14*(1-N($L14)),"") | AA14: =IF($Y14=1,IF($K14="TTC",$Z14/(1+$V14),$Z14),"") | AB14: =IF($Y14=1,IF($K14="TTC",$Z14-$AA14,$AA14*$V14),"") | AC14: =IF($Y14=1,$AA14*$U14*$M14,"") | AD14: =IF($Y14=1,$AC14/SUMIFS($AC$6:$AC$205,$C$6:$C$205,$C14,$Y$6:$Y$205,1),"") | AE14: =IF($Y14=1,(INDEX(Fournisseurs!$J$5:$J$24,MATCH($C14,Fournisseurs!$A$5:$A$24,0))+INDEX(Fournisseurs!$K$5:$K$24,MATCH($C14,Fournisseurs!$A$5:$A$24,0)))*$U14*$AD14/($I14*$M14),"") | AF14: =IF($Y14=1,INDEX(Fournisseurs!$L$5:$L$24,MATCH($C14,Fournisseurs!$A$5:$A$24,0))*$AD14/($I14*$M14),"") | AG14: =IF($Y14=1,$AA14*$U14/$I14,"") | AH14: =IF($Y14=1,$AB14*$U14/$I14,"") | AI14: =IF($Y14=1,IF(AND(Paramètres!$B$4="EFFECTIVE",$W14="CH",$AB14>0),1,0),"") | AJ14: =IF($Y14=1,IF($X14<>"CH",($AG14+$AE14+$AF14)*Paramètres!$B$14,0),"") | AK14: =IF($Y14=1,$AG14+IF($AI14=1,0,$AH14)+$AE14+$AF14+IF(Paramètres!$B$4="NOT_REGISTERED",$AJ14,0),"") | AL14: =IF($Y14=1,($AK14+Paramètres!$B$7+Paramètres!$B$8+Paramètres!$B$9+Paramètres!$B$10)/((1-Paramètres!$B$11)/(1+Paramètres!$B$5)-Paramètres!$B$6),"") | AM14: =IF(AND($Y14=1,ISNUMBER($R14)),IF($R14>0,$AL14/$R14-1,""),"") | AN14: =IF(AND($Y14=1,ISNUMBER($R14)),IF($R14>0,$R14/(1+Paramètres!$B$5)-$AK14-($R14*Paramètres!$B$6+Paramètres!$B$7)-Paramètres!$B$8-Paramètres!$B$9-Paramètres!$B$10,""),"") | AO14: =IF(ISNUMBER($AN14),$AN14/($R14/(1+Paramètres!$B$5)),"") | AP14: =IF($A14="","",IF($Y14<>1,"INCOMPLET",IF(NOT(ISNUMBER($AM14)),"SANS RÉF. MARCHÉ",IF($AM14<=Paramètres!$B$12,"OK",IF(AND($AO14>=Paramètres!$B$15,$AN14>=Paramètres!$B$16),"À REVOIR","NON RENTABLE"))))) -> INCOMPLET | AQ14: =TRIM(IF(AND($Y14=1,ISNUMBER($N14)),IF($M14<$N14,"MOQ ",""),"")&IF(AND($Y14=1,ISNUMBER($O14)),IF($O14<$I14*$M14,"DISPO ",""),"")&IF($S14="O","FICTIF ","")&IF($Y14=1,IF(AND($K14="TTC",$W14<>"CH"),"TVA-ÉTRANGÈRE ",""),"")) | AR14: =IF($Y14=1,COUNTIFS($A$6:$A$205,$A14,$AK$6:$AK$205,"<"&$AK14,$Y$6:$Y$205,1)+1,"") | AS14: =IF(ISNUMBER($AR14),$A14&"|"&$AR14,"") | AT14: =IF($Y14=1,$AK14*$I14*$M14,"")
A15: REF-19 | B15: Tripack ou bundle Méga-Évolution – Chaos Ascendant – FR | C15: Asmodee France | G15: Méga-Évolution – Chaos Ascendant | H15: tripack | S15: N | T15: =IF($C15="","",IFERROR(INDEX(Fournisseurs!$C$5:$C$24,MATCH($C15,Fournisseurs!$A$5:$A$24,0)),"")) -> 0 | U15: =IF($C15="","",IFERROR(INDEX(Fournisseurs!$D$5:$D$24,MATCH($C15,Fournisseurs!$A$5:$A$24,0)),"")) -> 0 | V15: =IF($C15="","",IFERROR(INDEX(Fournisseurs!$G$5:$G$24,MATCH($C15,Fournisseurs!$A$5:$A$24,0)),"")) -> 0 | W15: =IF($C15="","",IFERROR(INDEX(Fournisseurs!$H$5:$H$24,MATCH($C15,Fournisseurs!$A$5:$A$24,0)),"")) -> 0 | X15: =IF($C15="","",IFERROR(INDEX(Fournisseurs!$B$5:$B$24,MATCH($C15,Fournisseurs!$A$5:$A$24,0)),"")) -> 0 | Y15: =IF($A15="","",IF(AND($A15<>"",$C15<>"",ISNUMBER($I15),ISNUMBER($J15),ISNUMBER($M15)),IF(AND($I15>=1,$J15>0,OR($K15="HT",$K15="TTC"),$M15>=1,IFERROR(INDEX(Fournisseurs!$T$5:$T$24,MATCH($C15,Fournisseurs!$A$5:$A$24,0)),0)=1),1,0),0)) -> 0 | Z15: =IF($Y15=1,$J15*(1-N($L15)),"") | AA15: =IF($Y15=1,IF($K15="TTC",$Z15/(1+$V15),$Z15),"") | AB15: =IF($Y15=1,IF($K15="TTC",$Z15-$AA15,$AA15*$V15),"") | AC15: =IF($Y15=1,$AA15*$U15*$M15,"") | AD15: =IF($Y15=1,$AC15/SUMIFS($AC$6:$AC$205,$C$6:$C$205,$C15,$Y$6:$Y$205,1),"") | AE15: =IF($Y15=1,(INDEX(Fournisseurs!$J$5:$J$24,MATCH($C15,Fournisseurs!$A$5:$A$24,0))+INDEX(Fournisseurs!$K$5:$K$24,MATCH($C15,Fournisseurs!$A$5:$A$24,0)))*$U15*$AD15/($I15*$M15),"") | AF15: =IF($Y15=1,INDEX(Fournisseurs!$L$5:$L$24,MATCH($C15,Fournisseurs!$A$5:$A$24,0))*$AD15/($I15*$M15),"") | AG15: =IF($Y15=1,$AA15*$U15/$I15,"") | AH15: =IF($Y15=1,$AB15*$U15/$I15,"") | AI15: =IF($Y15=1,IF(AND(Paramètres!$B$4="EFFECTIVE",$W15="CH",$AB15>0),1,0),"") | AJ15: =IF($Y15=1,IF($X15<>"CH",($AG15+$AE15+$AF15)*Paramètres!$B$14,0),"") | AK15: =IF($Y15=1,$AG15+IF($AI15=1,0,$AH15)+$AE15+$AF15+IF(Paramètres!$B$4="NOT_REGISTERED",$AJ15,0),"") | AL15: =IF($Y15=1,($AK15+Paramètres!$B$7+Paramètres!$B$8+Paramètres!$B$9+Paramètres!$B$10)/((1-Paramètres!$B$11)/(1+Paramètres!$B$5)-Paramètres!$B$6),"") | AM15: =IF(AND($Y15=1,ISNUMBER($R15)),IF($R15>0,$AL15/$R15-1,""),"") | AN15: =IF(AND($Y15=1,ISNUMBER($R15)),IF($R15>0,$R15/(1+Paramètres!$B$5)-$AK15-($R15*Paramètres!$B$6+Paramètres!$B$7)-Paramètres!$B$8-Paramètres!$B$9-Paramètres!$B$10,""),"") | AO15: =IF(ISNUMBER($AN15),$AN15/($R15/(1+Paramètres!$B$5)),"") | AP15: =IF($A15="","",IF($Y15<>1,"INCOMPLET",IF(NOT(ISNUMBER($AM15)),"SANS RÉF. MARCHÉ",IF($AM15<=Paramètres!$B$12,"OK",IF(AND($AO15>=Paramètres!$B$15,$AN15>=Paramètres!$B$16),"À REVOIR","NON RENTABLE"))))) -> INCOMPLET | AQ15: =TRIM(IF(AND($Y15=1,ISNUMBER($N15)),IF($M15<$N15,"MOQ ",""),"")&IF(AND($Y15=1,ISNUMBER($O15)),IF($O15<$I15*$M15,"DISPO ",""),"")&IF($S15="O","FICTIF ","")&IF($Y15=1,IF(AND($K15="TTC",$W15<>"CH"),"TVA-ÉTRANGÈRE ",""),"")) | AR15: =IF($Y15=1,COUNTIFS($A$6:$A$205,$A15,$AK$6:$AK$205,"<"&$AK15,$Y$6:$Y$205,1)+1,"") | AS15: =IF(ISNUMBER($AR15),$A15&"|"&$AR15,"") | AT15: =IF($Y15=1,$AK15*$I15*$M15,"")
A16: REF-04 | B16: Coffret 30ᵉ Anniversaire Nymphali-ex – FR | C16: Asmodee France | G16: 30ᵉ Anniversaire | H16: coffret | S16: N | T16: =IF($C16="","",IFERROR(INDEX(Fournisseurs!$C$5:$C$24,MATCH($C16,Fournisseurs!$A$5:$A$24,0)),"")) -> 0 | U16: =IF($C16="","",IFERROR(INDEX(Fournisseurs!$D$5:$D$24,MATCH($C16,Fournisseurs!$A$5:$A$24,0)),"")) -> 0 | V16: =IF($C16="","",IFERROR(INDEX(Fournisseurs!$G$5:$G$24,MATCH($C16,Fournisseurs!$A$5:$A$24,0)),"")) -> 0 | W16: =IF($C16="","",IFERROR(INDEX(Fournisseurs!$H$5:$H$24,MATCH($C16,Fournisseurs!$A$5:$A$24,0)),"")) -> 0 | X16: =IF($C16="","",IFERROR(INDEX(Fournisseurs!$B$5:$B$24,MATCH($C16,Fournisseurs!$A$5:$A$24,0)),"")) -> 0 | Y16: =IF($A16="","",IF(AND($A16<>"",$C16<>"",ISNUMBER($I16),ISNUMBER($J16),ISNUMBER($M16)),IF(AND($I16>=1,$J16>0,OR($K16="HT",$K16="TTC"),$M16>=1,IFERROR(INDEX(Fournisseurs!$T$5:$T$24,MATCH($C16,Fournisseurs!$A$5:$A$24,0)),0)=1),1,0),0)) -> 0 | Z16: =IF($Y16=1,$J16*(1-N($L16)),"") | AA16: =IF($Y16=1,IF($K16="TTC",$Z16/(1+$V16),$Z16),"") | AB16: =IF($Y16=1,IF($K16="TTC",$Z16-$AA16,$AA16*$V16),"") | AC16: =IF($Y16=1,$AA16*$U16*$M16,"") | AD16: =IF($Y16=1,$AC16/SUMIFS($AC$6:$AC$205,$C$6:$C$205,$C16,$Y$6:$Y$205,1),"") | AE16: =IF($Y16=1,(INDEX(Fournisseurs!$J$5:$J$24,MATCH($C16,Fournisseurs!$A$5:$A$24,0))+INDEX(Fournisseurs!$K$5:$K$24,MATCH($C16,Fournisseurs!$A$5:$A$24,0)))*$U16*$AD16/($I16*$M16),"") | AF16: =IF($Y16=1,INDEX(Fournisseurs!$L$5:$L$24,MATCH($C16,Fournisseurs!$A$5:$A$24,0))*$AD16/($I16*$M16),"") | AG16: =IF($Y16=1,$AA16*$U16/$I16,"") | AH16: =IF($Y16=1,$AB16*$U16/$I16,"") | AI16: =IF($Y16=1,IF(AND(Paramètres!$B$4="EFFECTIVE",$W16="CH",$AB16>0),1,0),"") | AJ16: =IF($Y16=1,IF($X16<>"CH",($AG16+$AE16+$AF16)*Paramètres!$B$14,0),"") | AK16: =IF($Y16=1,$AG16+IF($AI16=1,0,$AH16)+$AE16+$AF16+IF(Paramètres!$B$4="NOT_REGISTERED",$AJ16,0),"") | AL16: =IF($Y16=1,($AK16+Paramètres!$B$7+Paramètres!$B$8+Paramètres!$B$9+Paramètres!$B$10)/((1-Paramètres!$B$11)/(1+Paramètres!$B$5)-Paramètres!$B$6),"") | AM16: =IF(AND($Y16=1,ISNUMBER($R16)),IF($R16>0,$AL16/$R16-1,""),"") | AN16: =IF(AND($Y16=1,ISNUMBER($R16)),IF($R16>0,$R16/(1+Paramètres!$B$5)-$AK16-($R16*Paramètres!$B$6+Paramètres!$B$7)-Paramètres!$B$8-Paramètres!$B$9-Paramètres!$B$10,""),"") | AO16: =IF(ISNUMBER($AN16),$AN16/($R16/(1+Paramètres!$B$5)),"") | AP16: =IF($A16="","",IF($Y16<>1,"INCOMPLET",IF(NOT(ISNUMBER($AM16)),"SANS RÉF. MARCHÉ",IF($AM16<=Paramètres!$B$12,"OK",IF(AND($AO16>=Paramètres!$B$15,$AN16>=Paramètres!$B$16),"À REVOIR","NON RENTABLE"))))) -> INCOMPLET | AQ16: =TRIM(IF(AND($Y16=1,ISNUMBER($N16)),IF($M16<$N16,"MOQ ",""),"")&IF(AND($Y16=1,ISNUMBER($O16)),IF($O16<$I16*$M16,"DISPO ",""),"")&IF($S16="O","FICTIF ","")&IF($Y16=1,IF(AND($K16="TTC",$W16<>"CH"),"TVA-ÉTRANGÈRE ",""),"")) | AR16: =IF($Y16=1,COUNTIFS($A$6:$A$205,$A16,$AK$6:$AK$205,"<"&$AK16,$Y$6:$Y$205,1)+1,"") | AS16: =IF(ISNUMBER($AR16),$A16&"|"&$AR16,"") | AT16: =IF($Y16=1,$AK16*$I16*$M16,"")
A17: REF-20 | B17: Coffret ou collection – Équilibre Parfait ou Héros Transcendants – FR | C17: Asmodee France | G17: Méga-Évolution – Équilibre Parfait / Héros Transcendants | H17: coffret | S17: N | T17: =IF($C17="","",IFERROR(INDEX(Fournisseurs!$C$5:$C$24,MATCH($C17,Fournisseurs!$A$5:$A$24,0)),"")) -> 0 | U17: =IF($C17="","",IFERROR(INDEX(Fournisseurs!$D$5:$D$24,MATCH($C17,Fournisseurs!$A$5:$A$24,0)),"")) -> 0 | V17: =IF($C17="","",IFERROR(INDEX(Fournisseurs!$G$5:$G$24,MATCH($C17,Fournisseurs!$A$5:$A$24,0)),"")) -> 0 | W17: =IF($C17="","",IFERROR(INDEX(Fournisseurs!$H$5:$H$24,MATCH($C17,Fournisseurs!$A$5:$A$24,0)),"")) -> 0 | X17: =IF($C17="","",IFERROR(INDEX(Fournisseurs!$B$5:$B$24,MATCH($C17,Fournisseurs!$A$5:$A$24,0)),"")) -> 0 | Y17: =IF($A17="","",IF(AND($A17<>"",$C17<>"",ISNUMBER($I17),ISNUMBER($J17),ISNUMBER($M17)),IF(AND($I17>=1,$J17>0,OR($K17="HT",$K17="TTC"),$M17>=1,IFERROR(INDEX(Fournisseurs!$T$5:$T$24,MATCH($C17,Fournisseurs!$A$5:$A$24,0)),0)=1),1,0),0)) -> 0 | Z17: =IF($Y17=1,$J17*(1-N($L17)),"") | AA17: =IF($Y17=1,IF($K17="TTC",$Z17/(1+$V17),$Z17),"") | AB17: =IF($Y17=1,IF($K17="TTC",$Z17-$AA17,$AA17*$V17),"") | AC17: =IF($Y17=1,$AA17*$U17*$M17,"") | AD17: =IF($Y17=1,$AC17/SUMIFS($AC$6:$AC$205,$C$6:$C$205,$C17,$Y$6:$Y$205,1),"") | AE17: =IF($Y17=1,(INDEX(Fournisseurs!$J$5:$J$24,MATCH($C17,Fournisseurs!$A$5:$A$24,0))+INDEX(Fournisseurs!$K$5:$K$24,MATCH($C17,Fournisseurs!$A$5:$A$24,0)))*$U17*$AD17/($I17*$M17),"") | AF17: =IF($Y17=1,INDEX(Fournisseurs!$L$5:$L$24,MATCH($C17,Fournisseurs!$A$5:$A$24,0))*$AD17/($I17*$M17),"") | AG17: =IF($Y17=1,$AA17*$U17/$I17,"") | AH17: =IF($Y17=1,$AB17*$U17/$I17,"") | AI17: =IF($Y17=1,IF(AND(Paramètres!$B$4="EFFECTIVE",$W17="CH",$AB17>0),1,0),"") | AJ17: =IF($Y17=1,IF($X17<>"CH",($AG17+$AE17+$AF17)*Paramètres!$B$14,0),"") | AK17: =IF($Y17=1,$AG17+IF($AI17=1,0,$AH17)+$AE17+$AF17+IF(Paramètres!$B$4="NOT_REGISTERED",$AJ17,0),"") | AL17: =IF($Y17=1,($AK17+Paramètres!$B$7+Paramètres!$B$8+Paramètres!$B$9+Paramètres!$B$10)/((1-Paramètres!$B$11)/(1+Paramètres!$B$5)-Paramètres!$B$6),"") | AM17: =IF(AND($Y17=1,ISNUMBER($R17)),IF($R17>0,$AL17/$R17-1,""),"") | AN17: =IF(AND($Y17=1,ISNUMBER($R17)),IF($R17>0,$R17/(1+Paramètres!$B$5)-$AK17-($R17*Paramètres!$B$6+Paramètres!$B$7)-Paramètres!$B$8-Paramètres!$B$9-Paramètres!$B$10,""),"") | AO17: =IF(ISNUMBER($AN17),$AN17/($R17/(1+Paramètres!$B$5)),"") | AP17: =IF($A17="","",IF($Y17<>1,"INCOMPLET",IF(NOT(ISNUMBER($AM17)),"SANS RÉF. MARCHÉ",IF($AM17<=Paramètres!$B$12,"OK",IF(AND($AO17>=Paramètres!$B$15,$AN17>=Paramètres!$B$16),"À REVOIR","NON RENTABLE"))))) -> INCOMPLET | AQ17: =TRIM(IF(AND($Y17=1,ISNUMBER($N17)),IF($M17<$N17,"MOQ ",""),"")&IF(AND($Y17=1,ISNUMBER($O17)),IF($O17<$I17*$M17,"DISPO ",""),"")&IF($S17="O","FICTIF ","")&IF($Y17=1,IF(AND($K17="TTC",$W17<>"CH"),"TVA-ÉTRANGÈRE ",""),"")) | AR17: =IF($Y17=1,COUNTIFS($A$6:$A$205,$A17,$AK$6:$AK$205,"<"&$AK17,$Y$6:$Y$205,1)+1,"") | AS17: =IF(ISNUMBER($AR17),$A17&"|"&$AR17,"") | AT17: =IF($Y17=1,$AK17*$I17*$M17,"")
A18: REF-16 | B18: Protège-cartes format standard (paquet) | C18: Asmodee France | H18: accessoire | S18: N | T18: =IF($C18="","",IFERROR(INDEX(Fournisseurs!$C$5:$C$24,MATCH($C18,Fournisseurs!$A$5:$A$24,0)),"")) -> 0 | U18: =IF($C18="","",IFERROR(INDEX(Fournisseurs!$D$5:$D$24,MATCH($C18,Fournisseurs!$A$5:$A$24,0)),"")) -> 0 | V18: =IF($C18="","",IFERROR(INDEX(Fournisseurs!$G$5:$G$24,MATCH($C18,Fournisseurs!$A$5:$A$24,0)),"")) -> 0 | W18: =IF($C18="","",IFERROR(INDEX(Fournisseurs!$H$5:$H$24,MATCH($C18,Fournisseurs!$A$5:$A$24,0)),"")) -> 0 | X18: =IF($C18="","",IFERROR(INDEX(Fournisseurs!$B$5:$B$24,MATCH($C18,Fournisseurs!$A$5:$A$24,0)),"")) -> 0 | Y18: =IF($A18="","",IF(AND($A18<>"",$C18<>"",ISNUMBER($I18),ISNUMBER($J18),ISNUMBER($M18)),IF(AND($I18>=1,$J18>0,OR($K18="HT",$K18="TTC"),$M18>=1,IFERROR(INDEX(Fournisseurs!$T$5:$T$24,MATCH($C18,Fournisseurs!$A$5:$A$24,0)),0)=1),1,0),0)) -> 0 | Z18: =IF($Y18=1,$J18*(1-N($L18)),"") | AA18: =IF($Y18=1,IF($K18="TTC",$Z18/(1+$V18),$Z18),"") | AB18: =IF($Y18=1,IF($K18="TTC",$Z18-$AA18,$AA18*$V18),"") | AC18: =IF($Y18=1,$AA18*$U18*$M18,"") | AD18: =IF($Y18=1,$AC18/SUMIFS($AC$6:$AC$205,$C$6:$C$205,$C18,$Y$6:$Y$205,1),"") | AE18: =IF($Y18=1,(INDEX(Fournisseurs!$J$5:$J$24,MATCH($C18,Fournisseurs!$A$5:$A$24,0))+INDEX(Fournisseurs!$K$5:$K$24,MATCH($C18,Fournisseurs!$A$5:$A$24,0)))*$U18*$AD18/($I18*$M18),"") | AF18: =IF($Y18=1,INDEX(Fournisseurs!$L$5:$L$24,MATCH($C18,Fournisseurs!$A$5:$A$24,0))*$AD18/($I18*$M18),"") | AG18: =IF($Y18=1,$AA18*$U18/$I18,"") | AH18: =IF($Y18=1,$AB18*$U18/$I18,"") | AI18: =IF($Y18=1,IF(AND(Paramètres!$B$4="EFFECTIVE",$W18="CH",$AB18>0),1,0),"") | AJ18: =IF($Y18=1,IF($X18<>"CH",($AG18+$AE18+$AF18)*Paramètres!$B$14,0),"") | AK18: =IF($Y18=1,$AG18+IF($AI18=1,0,$AH18)+$AE18+$AF18+IF(Paramètres!$B$4="NOT_REGISTERED",$AJ18,0),"") | AL18: =IF($Y18=1,($AK18+Paramètres!$B$7+Paramètres!$B$8+Paramètres!$B$9+Paramètres!$B$10)/((1-Paramètres!$B$11)/(1+Paramètres!$B$5)-Paramètres!$B$6),"") | AM18: =IF(AND($Y18=1,ISNUMBER($R18)),IF($R18>0,$AL18/$R18-1,""),"") | AN18: =IF(AND($Y18=1,ISNUMBER($R18)),IF($R18>0,$R18/(1+Paramètres!$B$5)-$AK18-($R18*Paramètres!$B$6+Paramètres!$B$7)-Paramètres!$B$8-Paramètres!$B$9-Paramètres!$B$10,""),"") | AO18: =IF(ISNUMBER($AN18),$AN18/($R18/(1+Paramètres!$B$5)),"") | AP18: =IF($A18="","",IF($Y18<>1,"INCOMPLET",IF(NOT(ISNUMBER($AM18)),"SANS RÉF. MARCHÉ",IF($AM18<=Paramètres!$B$12,"OK",IF(AND($AO18>=Paramètres!$B$15,$AN18>=Paramètres!$B$16),"À REVOIR","NON RENTABLE"))))) -> INCOMPLET | AQ18: =TRIM(IF(AND($Y18=1,ISNUMBER($N18)),IF($M18<$N18,"MOQ ",""),"")&IF(AND($Y18=1,ISNUMBER($O18)),IF($O18<$I18*$M18,"DISPO ",""),"")&IF($S18="O","FICTIF ","")&IF($Y18=1,IF(AND($K18="TTC",$W18<>"CH"),"TVA-ÉTRANGÈRE ",""),"")) | AR18: =IF($Y18=1,COUNTIFS($A$6:$A$205,$A18,$AK$6:$AK$205,"<"&$AK18,$Y$6:$Y$205,1)+1,"") | AS18: =IF(ISNUMBER($AR18),$A18&"|"&$AR18,"") | AT18: =IF($Y18=1,$AK18*$I18*$M18,"")
A19: REF-17 | B19: Classeur 9 cases | C19: Asmodee France | H19: accessoire | S19: N | T19: =IF($C19="","",IFERROR(INDEX(Fournisseurs!$C$5:$C$24,MATCH($C19,Fournisseurs!$A$5:$A$24,0)),"")) -> 0 | U19: =IF($C19="","",IFERROR(INDEX(Fournisseurs!$D$5:$D$24,MATCH($C19,Fournisseurs!$A$5:$A$24,0)),"")) -> 0 | V19: =IF($C19="","",IFERROR(INDEX(Fournisseurs!$G$5:$G$24,MATCH($C19,Fournisseurs!$A$5:$A$24,0)),"")) -> 0 | W19: =IF($C19="","",IFERROR(INDEX(Fournisseurs!$H$5:$H$24,MATCH($C19,Fournisseurs!$A$5:$A$24,0)),"")) -> 0 | X19: =IF($C19="","",IFERROR(INDEX(Fournisseurs!$B$5:$B$24,MATCH($C19,Fournisseurs!$A$5:$A$24,0)),"")) -> 0 | Y19: =IF($A19="","",IF(AND($A19<>"",$C19<>"",ISNUMBER($I19),ISNUMBER($J19),ISNUMBER($M19)),IF(AND($I19>=1,$J19>0,OR($K19="HT",$K19="TTC"),$M19>=1,IFERROR(INDEX(Fournisseurs!$T$5:$T$24,MATCH($C19,Fournisseurs!$A$5:$A$24,0)),0)=1),1,0),0)) -> 0 | Z19: =IF($Y19=1,$J19*(1-N($L19)),"") | AA19: =IF($Y19=1,IF($K19="TTC",$Z19/(1+$V19),$Z19),"") | AB19: =IF($Y19=1,IF($K19="TTC",$Z19-$AA19,$AA19*$V19),"") | AC19: =IF($Y19=1,$AA19*$U19*$M19,"") | AD19: =IF($Y19=1,$AC19/SUMIFS($AC$6:$AC$205,$C$6:$C$205,$C19,$Y$6:$Y$205,1),"") | AE19: =IF($Y19=1,(INDEX(Fournisseurs!$J$5:$J$24,MATCH($C19,Fournisseurs!$A$5:$A$24,0))+INDEX(Fournisseurs!$K$5:$K$24,MATCH($C19,Fournisseurs!$A$5:$A$24,0)))*$U19*$AD19/($I19*$M19),"") | AF19: =IF($Y19=1,INDEX(Fournisseurs!$L$5:$L$24,MATCH($C19,Fournisseurs!$A$5:$A$24,0))*$AD19/($I19*$M19),"") | AG19: =IF($Y19=1,$AA19*$U19/$I19,"") | AH19: =IF($Y19=1,$AB19*$U19/$I19,"") | AI19: =IF($Y19=1,IF(AND(Paramètres!$B$4="EFFECTIVE",$W19="CH",$AB19>0),1,0),"") | AJ19: =IF($Y19=1,IF($X19<>"CH",($AG19+$AE19+$AF19)*Paramètres!$B$14,0),"") | AK19: =IF($Y19=1,$AG19+IF($AI19=1,0,$AH19)+$AE19+$AF19+IF(Paramètres!$B$4="NOT_REGISTERED",$AJ19,0),"") | AL19: =IF($Y19=1,($AK19+Paramètres!$B$7+Paramètres!$B$8+Paramètres!$B$9+Paramètres!$B$10)/((1-Paramètres!$B$11)/(1+Paramètres!$B$5)-Paramètres!$B$6),"") | AM19: =IF(AND($Y19=1,ISNUMBER($R19)),IF($R19>0,$AL19/$R19-1,""),"") | AN19: =IF(AND($Y19=1,ISNUMBER($R19)),IF($R19>0,$R19/(1+Paramètres!$B$5)-$AK19-($R19*Paramètres!$B$6+Paramètres!$B$7)-Paramètres!$B$8-Paramètres!$B$9-Paramètres!$B$10,""),"") | AO19: =IF(ISNUMBER($AN19),$AN19/($R19/(1+Paramètres!$B$5)),"") | AP19: =IF($A19="","",IF($Y19<>1,"INCOMPLET",IF(NOT(ISNUMBER($AM19)),"SANS RÉF. MARCHÉ",IF($AM19<=Paramètres!$B$12,"OK",IF(AND($AO19>=Paramètres!$B$15,$AN19>=Paramètres!$B$16),"À REVOIR","NON RENTABLE"))))) -> INCOMPLET | AQ19: =TRIM(IF(AND($Y19=1,ISNUMBER($N19)),IF($M19<$N19,"MOQ ",""),"")&IF(AND($Y19=1,ISNUMBER($O19)),IF($O19<$I19*$M19,"DISPO ",""),"")&IF($S19="O","FICTIF ","")&IF($Y19=1,IF(AND($K19="TTC",$W19<>"CH"),"TVA-ÉTRANGÈRE ",""),"")) | AR19: =IF($Y19=1,COUNTIFS($A$6:$A$205,$A19,$AK$6:$AK$205,"<"&$AK19,$Y$6:$Y$205,1)+1,"") | AS19: =IF(ISNUMBER($AR19),$A19&"|"&$AR19,"") | AT19: =IF($Y19=1,$AK19*$I19*$M19,"")
A20: REF-03 | B20: Mini-Tin 30ᵉ Anniversaire – FR | C20: Asmodee France | G20: 30ᵉ Anniversaire | H20: coffret | S20: N | T20: =IF($C20="","",IFERROR(INDEX(Fournisseurs!$C$5:$C$24,MATCH($C20,Fournisseurs!$A$5:$A$24,0)),"")) -> 0 | U20: =IF($C20="","",IFERROR(INDEX(Fournisseurs!$D$5:$D$24,MATCH($C20,Fournisseurs!$A$5:$A$24,0)),"")) -> 0 | V20: =IF($C20="","",IFERROR(INDEX(Fournisseurs!$G$5:$G$24,MATCH($C20,Fournisseurs!$A$5:$A$24,0)),"")) -> 0 | W20: =IF($C20="","",IFERROR(INDEX(Fournisseurs!$H$5:$H$24,MATCH($C20,Fournisseurs!$A$5:$A$24,0)),"")) -> 0 | X20: =IF($C20="","",IFERROR(INDEX(Fournisseurs!$B$5:$B$24,MATCH($C20,Fournisseurs!$A$5:$A$24,0)),"")) -> 0 | Y20: =IF($A20="","",IF(AND($A20<>"",$C20<>"",ISNUMBER($I20),ISNUMBER($J20),ISNUMBER($M20)),IF(AND($I20>=1,$J20>0,OR($K20="HT",$K20="TTC"),$M20>=1,IFERROR(INDEX(Fournisseurs!$T$5:$T$24,MATCH($C20,Fournisseurs!$A$5:$A$24,0)),0)=1),1,0),0)) -> 0 | Z20: =IF($Y20=1,$J20*(1-N($L20)),"") | AA20: =IF($Y20=1,IF($K20="TTC",$Z20/(1+$V20),$Z20),"") | AB20: =IF($Y20=1,IF($K20="TTC",$Z20-$AA20,$AA20*$V20),"") | AC20: =IF($Y20=1,$AA20*$U20*$M20,"") | AD20: =IF($Y20=1,$AC20/SUMIFS($AC$6:$AC$205,$C$6:$C$205,$C20,$Y$6:$Y$205,1),"") | AE20: =IF($Y20=1,(INDEX(Fournisseurs!$J$5:$J$24,MATCH($C20,Fournisseurs!$A$5:$A$24,0))+INDEX(Fournisseurs!$K$5:$K$24,MATCH($C20,Fournisseurs!$A$5:$A$24,0)))*$U20*$AD20/($I20*$M20),"") | AF20: =IF($Y20=1,INDEX(Fournisseurs!$L$5:$L$24,MATCH($C20,Fournisseurs!$A$5:$A$24,0))*$AD20/($I20*$M20),"") | AG20: =IF($Y20=1,$AA20*$U20/$I20,"") | AH20: =IF($Y20=1,$AB20*$U20/$I20,"") | AI20: =IF($Y20=1,IF(AND(Paramètres!$B$4="EFFECTIVE",$W20="CH",$AB20>0),1,0),"") | AJ20: =IF($Y20=1,IF($X20<>"CH",($AG20+$AE20+$AF20)*Paramètres!$B$14,0),"") | AK20: =IF($Y20=1,$AG20+IF($AI20=1,0,$AH20)+$AE20+$AF20+IF(Paramètres!$B$4="NOT_REGISTERED",$AJ20,0),"") | AL20: =IF($Y20=1,($AK20+Paramètres!$B$7+Paramètres!$B$8+Paramètres!$B$9+Paramètres!$B$10)/((1-Paramètres!$B$11)/(1+Paramètres!$B$5)-Paramètres!$B$6),"") | AM20: =IF(AND($Y20=1,ISNUMBER($R20)),IF($R20>0,$AL20/$R20-1,""),"") | AN20: =IF(AND($Y20=1,ISNUMBER($R20)),IF($R20>0,$R20/(1+Paramètres!$B$5)-$AK20-($R20*Paramètres!$B$6+Paramètres!$B$7)-Paramètres!$B$8-Paramètres!$B$9-Paramètres!$B$10,""),"") | AO20: =IF(ISNUMBER($AN20),$AN20/($R20/(1+Paramètres!$B$5)),"") | AP20: =IF($A20="","",IF($Y20<>1,"INCOMPLET",IF(NOT(ISNUMBER($AM20)),"SANS RÉF. MARCHÉ",IF($AM20<=Paramètres!$B$12,"OK",IF(AND($AO20>=Paramètres!$B$15,$AN20>=Paramètres!$B$16),"À REVOIR","NON RENTABLE"))))) -> INCOMPLET | AQ20: =TRIM(IF(AND($Y20=1,ISNUMBER($N20)),IF($M20<$N20,"MOQ ",""),"")&IF(AND($Y20=1,ISNUMBER($O20)),IF($O20<$I20*$M20,"DISPO ",""),"")&IF($S20="O","FICTIF ","")&IF($Y20=1,IF(AND($K20="TTC",$W20<>"CH"),"TVA-ÉTRANGÈRE ",""),"")) | AR20: =IF($Y20=1,COUNTIFS($A$6:$A$205,$A20,$AK$6:$AK$205,"<"&$AK20,$Y$6:$Y$205,1)+1,"") | AS20: =IF(ISNUMBER($AR20),$A20&"|"&$AR20,"") | AT20: =IF($Y20=1,$AK20*$I20*$M20,"")
A21: REF-05 | B21: Collection Classeur 30ᵉ Anniversaire – FR | C21: Asmodee France | G21: 30ᵉ Anniversaire | H21: coffret | S21: N | T21: =IF($C21="","",IFERROR(INDEX(Fournisseurs!$C$5:$C$24,MATCH($C21,Fournisseurs!$A$5:$A$24,0)),"")) -> 0 | U21: =IF($C21="","",IFERROR(INDEX(Fournisseurs!$D$5:$D$24,MATCH($C21,Fournisseurs!$A$5:$A$24,0)),"")) -> 0 | V21: =IF($C21="","",IFERROR(INDEX(Fournisseurs!$G$5:$G$24,MATCH($C21,Fournisseurs!$A$5:$A$24,0)),"")) -> 0 | W21: =IF($C21="","",IFERROR(INDEX(Fournisseurs!$H$5:$H$24,MATCH($C21,Fournisseurs!$A$5:$A$24,0)),"")) -> 0 | X21: =IF($C21="","",IFERROR(INDEX(Fournisseurs!$B$5:$B$24,MATCH($C21,Fournisseurs!$A$5:$A$24,0)),"")) -> 0 | Y21: =IF($A21="","",IF(AND($A21<>"",$C21<>"",ISNUMBER($I21),ISNUMBER($J21),ISNUMBER($M21)),IF(AND($I21>=1,$J21>0,OR($K21="HT",$K21="TTC"),$M21>=1,IFERROR(INDEX(Fournisseurs!$T$5:$T$24,MATCH($C21,Fournisseurs!$A$5:$A$24,0)),0)=1),1,0),0)) -> 0 | Z21: =IF($Y21=1,$J21*(1-N($L21)),"") | AA21: =IF($Y21=1,IF($K21="TTC",$Z21/(1+$V21),$Z21),"") | AB21: =IF($Y21=1,IF($K21="TTC",$Z21-$AA21,$AA21*$V21),"") | AC21: =IF($Y21=1,$AA21*$U21*$M21,"") | AD21: =IF($Y21=1,$AC21/SUMIFS($AC$6:$AC$205,$C$6:$C$205,$C21,$Y$6:$Y$205,1),"") | AE21: =IF($Y21=1,(INDEX(Fournisseurs!$J$5:$J$24,MATCH($C21,Fournisseurs!$A$5:$A$24,0))+INDEX(Fournisseurs!$K$5:$K$24,MATCH($C21,Fournisseurs!$A$5:$A$24,0)))*$U21*$AD21/($I21*$M21),"") | AF21: =IF($Y21=1,INDEX(Fournisseurs!$L$5:$L$24,MATCH($C21,Fournisseurs!$A$5:$A$24,0))*$AD21/($I21*$M21),"") | AG21: =IF($Y21=1,$AA21*$U21/$I21,"") | AH21: =IF($Y21=1,$AB21*$U21/$I21,"") | AI21: =IF($Y21=1,IF(AND(Paramètres!$B$4="EFFECTIVE",$W21="CH",$AB21>0),1,0),"") | AJ21: =IF($Y21=1,IF($X21<>"CH",($AG21+$AE21+$AF21)*Paramètres!$B$14,0),"") | AK21: =IF($Y21=1,$AG21+IF($AI21=1,0,$AH21)+$AE21+$AF21+IF(Paramètres!$B$4="NOT_REGISTERED",$AJ21,0),"") | AL21: =IF($Y21=1,($AK21+Paramètres!$B$7+Paramètres!$B$8+Paramètres!$B$9+Paramètres!$B$10)/((1-Paramètres!$B$11)/(1+Paramètres!$B$5)-Paramètres!$B$6),"") | AM21: =IF(AND($Y21=1,ISNUMBER($R21)),IF($R21>0,$AL21/$R21-1,""),"") | AN21: =IF(AND($Y21=1,ISNUMBER($R21)),IF($R21>0,$R21/(1+Paramètres!$B$5)-$AK21-($R21*Paramètres!$B$6+Paramètres!$B$7)-Paramètres!$B$8-Paramètres!$B$9-Paramètres!$B$10,""),"") | AO21: =IF(ISNUMBER($AN21),$AN21/($R21/(1+Paramètres!$B$5)),"") | AP21: =IF($A21="","",IF($Y21<>1,"INCOMPLET",IF(NOT(ISNUMBER($AM21)),"SANS RÉF. MARCHÉ",IF($AM21<=Paramètres!$B$12,"OK",IF(AND($AO21>=Paramètres!$B$15,$AN21>=Paramètres!$B$16),"À REVOIR","NON RENTABLE"))))) -> INCOMPLET | AQ21: =TRIM(IF(AND($Y21=1,ISNUMBER($N21)),IF($M21<$N21,"MOQ ",""),"")&IF(AND($Y21=1,ISNUMBER($O21)),IF($O21<$I21*$M21,"DISPO ",""),"")&IF($S21="O","FICTIF ","")&IF($Y21=1,IF(AND($K21="TTC",$W21<>"CH"),"TVA-ÉTRANGÈRE ",""),"")) | AR21: =IF($Y21=1,COUNTIFS($A$6:$A$205,$A21,$AK$6:$AK$205,"<"&$AK21,$Y$6:$Y$205,1)+1,"") | AS21: =IF(ISNUMBER($AR21),$A21&"|"&$AR21,"") | AT21: =IF($Y21=1,$AK21*$I21*$M21,"")
A22: REF-10 | B22: Coffret Dresseur d'Élite (ETB) Méga-Évolution – Chaos Ascendant – FR | C22: Asmodee France | G22: Méga-Évolution – Chaos Ascendant | H22: etb | S22: N | T22: =IF($C22="","",IFERROR(INDEX(Fournisseurs!$C$5:$C$24,MATCH($C22,Fournisseurs!$A$5:$A$24,0)),"")) -> 0 | U22: =IF($C22="","",IFERROR(INDEX(Fournisseurs!$D$5:$D$24,MATCH($C22,Fournisseurs!$A$5:$A$24,0)),"")) -> 0 | V22: =IF($C22="","",IFERROR(INDEX(Fournisseurs!$G$5:$G$24,MATCH($C22,Fournisseurs!$A$5:$A$24,0)),"")) -> 0 | W22: =IF($C22="","",IFERROR(INDEX(Fournisseurs!$H$5:$H$24,MATCH($C22,Fournisseurs!$A$5:$A$24,0)),"")) -> 0 | X22: =IF($C22="","",IFERROR(INDEX(Fournisseurs!$B$5:$B$24,MATCH($C22,Fournisseurs!$A$5:$A$24,0)),"")) -> 0 | Y22: =IF($A22="","",IF(AND($A22<>"",$C22<>"",ISNUMBER($I22),ISNUMBER($J22),ISNUMBER($M22)),IF(AND($I22>=1,$J22>0,OR($K22="HT",$K22="TTC"),$M22>=1,IFERROR(INDEX(Fournisseurs!$T$5:$T$24,MATCH($C22,Fournisseurs!$A$5:$A$24,0)),0)=1),1,0),0)) -> 0 | Z22: =IF($Y22=1,$J22*(1-N($L22)),"") | AA22: =IF($Y22=1,IF($K22="TTC",$Z22/(1+$V22),$Z22),"") | AB22: =IF($Y22=1,IF($K22="TTC",$Z22-$AA22,$AA22*$V22),"") | AC22: =IF($Y22=1,$AA22*$U22*$M22,"") | AD22: =IF($Y22=1,$AC22/SUMIFS($AC$6:$AC$205,$C$6:$C$205,$C22,$Y$6:$Y$205,1),"") | AE22: =IF($Y22=1,(INDEX(Fournisseurs!$J$5:$J$24,MATCH($C22,Fournisseurs!$A$5:$A$24,0))+INDEX(Fournisseurs!$K$5:$K$24,MATCH($C22,Fournisseurs!$A$5:$A$24,0)))*$U22*$AD22/($I22*$M22),"") | AF22: =IF($Y22=1,INDEX(Fournisseurs!$L$5:$L$24,MATCH($C22,Fournisseurs!$A$5:$A$24,0))*$AD22/($I22*$M22),"") | AG22: =IF($Y22=1,$AA22*$U22/$I22,"") | AH22: =IF($Y22=1,$AB22*$U22/$I22,"") | AI22: =IF($Y22=1,IF(AND(Paramètres!$B$4="EFFECTIVE",$W22="CH",$AB22>0),1,0),"") | AJ22: =IF($Y22=1,IF($X22<>"CH",($AG22+$AE22+$AF22)*Paramètres!$B$14,0),"") | AK22: =IF($Y22=1,$AG22+IF($AI22=1,0,$AH22)+$AE22+$AF22+IF(Paramètres!$B$4="NOT_REGISTERED",$AJ22,0),"") | AL22: =IF($Y22=1,($AK22+Paramètres!$B$7+Paramètres!$B$8+Paramètres!$B$9+Paramètres!$B$10)/((1-Paramètres!$B$11)/(1+Paramètres!$B$5)-Paramètres!$B$6),"") | AM22: =IF(AND($Y22=1,ISNUMBER($R22)),IF($R22>0,$AL22/$R22-1,""),"") | AN22: =IF(AND($Y22=1,ISNUMBER($R22)),IF($R22>0,$R22/(1+Paramètres!$B$5)-$AK22-($R22*Paramètres!$B$6+Paramètres!$B$7)-Paramètres!$B$8-Paramètres!$B$9-Paramètres!$B$10,""),"") | AO22: =IF(ISNUMBER($AN22),$AN22/($R22/(1+Paramètres!$B$5)),"") | AP22: =IF($A22="","",IF($Y22<>1,"INCOMPLET",IF(NOT(ISNUMBER($AM22)),"SANS RÉF. MARCHÉ",IF($AM22<=Paramètres!$B$12,"OK",IF(AND($AO22>=Paramètres!$B$15,$AN22>=Paramètres!$B$16),"À REVOIR","NON RENTABLE"))))) -> INCOMPLET | AQ22: =TRIM(IF(AND($Y22=1,ISNUMBER($N22)),IF($M22<$N22,"MOQ ",""),"")&IF(AND($Y22=1,ISNUMBER($O22)),IF($O22<$I22*$M22,"DISPO ",""),"")&IF($S22="O","FICTIF ","")&IF($Y22=1,IF(AND($K22="TTC",$W22<>"CH"),"TVA-ÉTRANGÈRE ",""),"")) | AR22: =IF($Y22=1,COUNTIFS($A$6:$A$205,$A22,$AK$6:$AK$205,"<"&$AK22,$Y$6:$Y$205,1)+1,"") | AS22: =IF(ISNUMBER($AR22),$A22&"|"&$AR22,"") | AT22: =IF($Y22=1,$AK22*$I22*$M22,"")
